<sdf version='1.9'>
  <model name='tiago'>
    <link name='base_footprint'>
      <inertial>
        <pose>-0.006614551510019534 -0.001026883623185807 0.1694989268017899 0 0 0</pose>
        <mass>63.432785800000012</mass>
        <inertia>
          <ixx>4.2856910504250019</ixx>
          <ixy>0.00053457622180893768</ixy>
          <ixz>0.12753168704114651</ixz>
          <iyy>4.3778241057675524</iyy>
          <iyz>0.016815511758942369</iyz>
          <izz>2.6927119293415811</izz>
        </inertia>
      </inertial>
      <collision name='base_footprint_fixed_joint_lump__base_link_collision'>
        <pose>0 0 0.0985 0 0 0</pose>
        <geometry>
          <mesh>
            <scale>1 1 1</scale>
            <uri>../../../../pmb2_robot/pmb2_description/meshes/base/high_resolution/base_collision.stl</uri>
          </mesh>
        </geometry>
        <surface>
          <contact>
            <ode/>
          </contact>
          <friction>
            <ode/>
          </friction>
        </surface>
      </collision>
      <collision name='base_footprint_fixed_joint_lump__base_antenna_left_link_collision_1'>
        <pose>-0.201 0.1062 0.3785000000000001 0 0 0</pose>
        <geometry>
          <cylinder>
            <length>0.17000000000000001</length>
            <radius>0.0050000000000000001</radius>
          </cylinder>
        </geometry>
        <surface>
          <contact>
            <ode/>
          </contact>
          <friction>
            <ode/>
          </friction>
        </surface>
      </collision>
      <collision name='base_footprint_fixed_joint_lump__base_antenna_right_link_collision_2'>
        <pose>-0.201 -0.1062 0.3785000000000001 0 0 0</pose>
        <geometry>
          <cylinder>
            <length>0.17000000000000001</length>
            <radius>0.0050000000000000001</radius>
          </cylinder>
        </geometry>
        <surface>
          <contact>
            <ode/>
          </contact>
          <friction>
            <ode/>
          </friction>
        </surface>
      </collision>
      <collision name='base_footprint_fixed_joint_lump__base_dock_link_collision_3'>
        <pose>0.2675 0 0.1595 0 0 0</pose>
        <geometry>
          <mesh>
            <scale>1 1 1</scale>
            <uri>../../../../pmb2_robot/pmb2_description/meshes/base/base_dock_link.stl</uri>
          </mesh>
        </geometry>
      </collision>
      <collision name='base_footprint_fixed_joint_lump__base_laser_link_collision_4'>
        <pose>0.202 0 0.0945 0 0 0</pose>
        <geometry>
          <cylinder>
            <length>0.01</length>
            <radius>0.01</radius>
          </cylinder>
        </geometry>
        <surface>
          <contact>
            <ode/>
          </contact>
          <friction>
            <ode/>
          </friction>
        </surface>
      </collision>
      <collision name='base_footprint_fixed_joint_lump__caster_back_left_2_link_collision_5'>
        <pose>-0.1895 0.102 0.02499999999999999 -1.570796326794896 0 0</pose>
        <geometry>
          <sphere>
            <radius>0.025000000000000001</radius>
          </sphere>
        </geometry>
        <surface>
          <contact>
            <ode>
              <kp>1000000</kp>
              <kd>100</kd>
              <max_vel>1</max_vel>
              <min_depth>0.002</min_depth>
            </ode>
          </contact>
          <friction>
            <ode>
              <mu>0.01</mu>
              <mu2>0.01</mu2>
            </ode>
          </friction>
        </surface>
      </collision>
      <collision name='base_footprint_fixed_joint_lump__caster_back_right_2_link_collision_6'>
        <pose>-0.1895 -0.102 0.02499999999999999 -1.570796326794896 0 0</pose>
        <geometry>
          <sphere>
            <radius>0.025000000000000001</radius>
          </sphere>
        </geometry>
        <surface>
          <contact>
            <ode>
              <kp>1000000</kp>
              <kd>100</kd>
              <max_vel>1</max_vel>
              <min_depth>0.002</min_depth>
            </ode>
          </contact>
          <friction>
            <ode>
              <mu>0.01</mu>
              <mu2>0.01</mu2>
            </ode>
          </friction>
        </surface>
      </collision>
      <collision name='base_footprint_fixed_joint_lump__caster_front_left_2_link_collision_7'>
        <pose>0.1535 0.102 0.02499999999999999 -1.570796326794896 0 0</pose>
        <geometry>
          <sphere>
            <radius>0.025000000000000001</radius>
          </sphere>
        </geometry>
        <surface>
          <contact>
            <ode>
              <kp>1000000</kp>
              <kd>100</kd>
              <max_vel>1</max_vel>
              <min_depth>0.002</min_depth>
            </ode>
          </contact>
          <friction>
            <ode>
              <mu>0.01</mu>
              <mu2>0.01</mu2>
            </ode>
          </friction>
        </surface>
      </collision>
      <collision name='base_footprint_fixed_joint_lump__caster_front_right_2_link_collision_8'>
        <pose>0.1535 -0.102 0.02499999999999999 -1.570796326794896 0 0</pose>
        <geometry>
          <sphere>
            <radius>0.025000000000000001</radius>
          </sphere>
        </geometry>
        <surface>
          <contact>
            <ode>
              <kp>1000000</kp>
              <kd>100</kd>
              <max_vel>1</max_vel>
              <min_depth>0.002</min_depth>
            </ode>
          </contact>
          <friction>
            <ode>
              <mu>0.01</mu>
              <mu2>0.01</mu2>
            </ode>
          </friction>
        </surface>
      </collision>
      <collision name='base_footprint_fixed_joint_lump__torso_fixed_column_link_collision_9'>
        <pose>-0.062 0 0.5665 0 0 0</pose>
        <geometry>
          <box>
            <size>0.232 0.265 0.45</size>
          </box>
        </geometry>
        <surface>
          <contact>
            <ode/>
          </contact>
          <friction>
            <ode/>
          </friction>
        </surface>
      </collision>
      <collision name='base_footprint_fixed_joint_lump__torso_fixed_link_collision_10'>
        <pose>0.02300000000000001 0 0.3115 0 0 0</pose>
        <geometry>
          <box>
            <size>0.4 0.25 0.04</size>
          </box>
        </geometry>
      </collision>
      <collision name='base_footprint_fixed_joint_lump__torso_fixed_link_collision_11'>
        <pose>-0.062 0 0.3415 0 0 0</pose>
        <geometry>
          <box>
            <size>0.25 0.25 0.1</size>
          </box>
        </geometry>
      </collision>
      <visual name='base_footprint_fixed_joint_lump__base_link_visual'>
        <pose>0 0 0.0985 0 0 0</pose>
        <geometry>
          <mesh>
            <scale>1 1 1</scale>
            <uri>../../../../pmb2_robot/pmb2_description/meshes/base/base.stl</uri>
          </mesh>
        </geometry>
        <material>
          <script>
            <name>Gazebo/White</name>
            <uri>file://media/materials/scripts/gazebo.material</uri>
          </script>
          <diffuse>1 1 1 1</diffuse>
          <ambient>1 1 1 1</ambient>
        </material>
      </visual>
      <visual name='base_footprint_fixed_joint_lump__base_antenna_left_link_visual_1'>
        <pose>-0.201 0.1062 0.2935 0 0 0</pose>
        <geometry>
          <mesh>
            <scale>1 1 1</scale>
            <uri>../../../../pmb2_robot/pmb2_description/meshes/objects/antenna.stl</uri>
          </mesh>
        </geometry>
        <material>
          <script>
            <name>Gazebo/Black</name>
            <uri>file://media/materials/scripts/gazebo.material</uri>
          </script>
          <diffuse>0 0 0 1</diffuse>
          <ambient>0 0 0 1</ambient>
        </material>
      </visual>
      <visual name='base_footprint_fixed_joint_lump__base_antenna_right_link_visual_2'>
        <pose>-0.201 -0.1062 0.2935 0 0 0</pose>
        <geometry>
          <mesh>
            <scale>1 1 1</scale>
            <uri>../../../../pmb2_robot/pmb2_description/meshes/objects/antenna.stl</uri>
          </mesh>
        </geometry>
        <material>
          <script>
            <name>Gazebo/Black</name>
            <uri>file://media/materials/scripts/gazebo.material</uri>
          </script>
          <diffuse>0 0 0 1</diffuse>
          <ambient>0 0 0 1</ambient>
        </material>
      </visual>
      <visual name='base_footprint_fixed_joint_lump__base_dock_link_visual_3'>
        <pose>0.2675 0 0.1595 0 0 0</pose>
        <geometry>
          <mesh>
            <scale>1 1 1</scale>
            <uri>../../../../pmb2_robot/pmb2_description/meshes/base/base_dock_link.stl</uri>
          </mesh>
        </geometry>
        <material>
          <diffuse>0.313725 0.313725 0.313725 1</diffuse>
          <ambient>0.313725 0.313725 0.313725 1</ambient>
        </material>
      </visual>
      <visual name='base_footprint_fixed_joint_lump__base_laser_link_visual_4'>
        <pose>0.202 0 0.0945 0 0 0</pose>
        <geometry>
          <mesh>
            <scale>1 1 1</scale>
            <uri>../../../../pal_urdf_utils/meshes/laser/sick_tim551.stl</uri>
          </mesh>
        </geometry>
        <material>
          <script>
            <name>Gazebo/DarkGrey</name>
            <uri>file://media/materials/scripts/gazebo.material</uri>
          </script>
          <diffuse>0.125 0.125 0.125 1</diffuse>
          <ambient>0.125 0.125 0.125 1</ambient>
        </material>
      </visual>
      <visual name='base_footprint_fixed_joint_lump__base_sonar_01_link_visual_5'>
        <pose>-0.183 -0.183 0.2715 0 0 -2.356194490192345</pose>
        <geometry>
          <mesh>
            <scale>1 1 1</scale>
            <uri>../../../../pal_urdf_utils/meshes/laser/srf05.stl</uri>
          </mesh>
        </geometry>
        <material>
          <script>
            <name>Gazebo/DarkGrey</name>
            <uri>file://media/materials/scripts/gazebo.material</uri>
          </script>
          <diffuse>0.125 0.125 0.125 1</diffuse>
          <ambient>0.125 0.125 0.125 1</ambient>
        </material>
      </visual>
      <visual name='base_footprint_fixed_joint_lump__base_sonar_02_link_visual_6'>
        <pose>-0.259 0 0.2715 0 0 3.141592653589793</pose>
        <geometry>
          <mesh>
            <scale>1 1 1</scale>
            <uri>../../../../pal_urdf_utils/meshes/laser/srf05.stl</uri>
          </mesh>
        </geometry>
        <material>
          <script>
            <name>Gazebo/DarkGrey</name>
            <uri>file://media/materials/scripts/gazebo.material</uri>
          </script>
          <diffuse>0.125 0.125 0.125 1</diffuse>
          <ambient>0.125 0.125 0.125 1</ambient>
        </material>
      </visual>
      <visual name='base_footprint_fixed_joint_lump__base_sonar_03_link_visual_7'>
        <pose>-0.183 0.183 0.2715 0 0 2.356194490192345</pose>
        <geometry>
          <mesh>
            <scale>1 1 1</scale>
            <uri>../../../../pal_urdf_utils/meshes/laser/srf05.stl</uri>
          </mesh>
        </geometry>
        <material>
          <script>
            <name>Gazebo/DarkGrey</name>
            <uri>file://media/materials/scripts/gazebo.material</uri>
          </script>
          <diffuse>0.125 0.125 0.125 1</diffuse>
          <ambient>0.125 0.125 0.125 1</ambient>
        </material>
      </visual>
      <visual name='base_footprint_fixed_joint_lump__caster_back_left_1_link_visual_8'>
        <pose>-0.1735 0.102 0.065 0 0 0</pose>
        <geometry>
          <mesh>
            <scale>1 1 1</scale>
            <uri>../../../../pmb2_robot/pmb2_description/meshes/wheels/caster_1.stl</uri>
          </mesh>
        </geometry>
        <material>
          <diffuse>0.875 0.875 0.875 1</diffuse>
          <ambient>0.875 0.875 0.875 1</ambient>
        </material>
      </visual>
      <visual name='base_footprint_fixed_joint_lump__caster_back_left_2_link_visual_9'>
        <pose>-0.1895 0.102 0.02499999999999999 -1.570796326794896 0 0</pose>
        <geometry>
          <mesh>
            <scale>1 1 1</scale>
            <uri>../../../../pmb2_robot/pmb2_description/meshes/wheels/caster_2.stl</uri>
          </mesh>
        </geometry>
        <material>
          <script>
            <name>Gazebo/DarkGrey</name>
            <uri>file://media/materials/scripts/gazebo.material</uri>
          </script>
          <diffuse>0.125 0.125 0.125 1</diffuse>
          <ambient>0.125 0.125 0.125 1</ambient>
        </material>
      </visual>
      <visual name='base_footprint_fixed_joint_lump__caster_back_right_1_link_visual_10'>
        <pose>-0.1735 -0.102 0.065 0 0 0</pose>
        <geometry>
          <mesh>
            <scale>1 1 1</scale>
            <uri>../../../../pmb2_robot/pmb2_description/meshes/wheels/caster_1.stl</uri>
          </mesh>
        </geometry>
        <material>
          <diffuse>0.875 0.875 0.875 1</diffuse>
          <ambient>0.875 0.875 0.875 1</ambient>
        </material>
      </visual>
      <visual name='base_footprint_fixed_joint_lump__caster_back_right_2_link_visual_11'>
        <pose>-0.1895 -0.102 0.02499999999999999 -1.570796326794896 0 0</pose>
        <geometry>
          <mesh>
            <scale>1 1 1</scale>
            <uri>../../../../pmb2_robot/pmb2_description/meshes/wheels/caster_2.stl</uri>
          </mesh>
        </geometry>
        <material>
          <script>
            <name>Gazebo/DarkGrey</name>
            <uri>file://media/materials/scripts/gazebo.material</uri>
          </script>
          <diffuse>0.125 0.125 0.125 1</diffuse>
          <ambient>0.125 0.125 0.125 1</ambient>
        </material>
      </visual>
      <visual name='base_footprint_fixed_joint_lump__caster_front_left_1_link_visual_12'>
        <pose>0.1695 0.102 0.065 0 0 0</pose>
        <geometry>
          <mesh>
            <scale>1 1 1</scale>
            <uri>../../../../pmb2_robot/pmb2_description/meshes/wheels/caster_1.stl</uri>
          </mesh>
        </geometry>
        <material>
          <diffuse>0.875 0.875 0.875 1</diffuse>
          <ambient>0.875 0.875 0.875 1</ambient>
        </material>
      </visual>
      <visual name='base_footprint_fixed_joint_lump__caster_front_left_2_link_visual_13'>
        <pose>0.1535 0.102 0.02499999999999999 -1.570796326794896 0 0</pose>
        <geometry>
          <mesh>
            <scale>1 1 1</scale>
            <uri>../../../../pmb2_robot/pmb2_description/meshes/wheels/caster_2.stl</uri>
          </mesh>
        </geometry>
        <material>
          <script>
            <name>Gazebo/DarkGrey</name>
            <uri>file://media/materials/scripts/gazebo.material</uri>
          </script>
          <diffuse>0.125 0.125 0.125 1</diffuse>
          <ambient>0.125 0.125 0.125 1</ambient>
        </material>
      </visual>
      <visual name='base_footprint_fixed_joint_lump__caster_front_right_1_link_visual_14'>
        <pose>0.1695 -0.102 0.065 0 0 0</pose>
        <geometry>
          <mesh>
            <scale>1 1 1</scale>
            <uri>../../../../pmb2_robot/pmb2_description/meshes/wheels/caster_1.stl</uri>
          </mesh>
        </geometry>
        <material>
          <diffuse>0.875 0.875 0.875 1</diffuse>
          <ambient>0.875 0.875 0.875 1</ambient>
        </material>
      </visual>
      <visual name='base_footprint_fixed_joint_lump__caster_front_right_2_link_visual_15'>
        <pose>0.1535 -0.102 0.02499999999999999 -1.570796326794896 0 0</pose>
        <geometry>
          <mesh>
            <scale>1 1 1</scale>
            <uri>../../../../pmb2_robot/pmb2_description/meshes/wheels/caster_2.stl</uri>
          </mesh>
        </geometry>
        <material>
          <script>
            <name>Gazebo/DarkGrey</name>
            <uri>file://media/materials/scripts/gazebo.material</uri>
          </script>
          <diffuse>0.125 0.125 0.125 1</diffuse>
          <ambient>0.125 0.125 0.125 1</ambient>
        </material>
      </visual>
      <visual name='base_footprint_fixed_joint_lump__torso_fixed_column_link_visual_16'>
        <pose>-0.062 0 0.5665 0 0 0</pose>
        <geometry>
          <box>
            <size>0.18 0.2 0.55</size>
          </box>
        </geometry>
        <material>
          <script>
            <name>Gazebo/DarkGrey</name>
            <uri>file://media/materials/scripts/gazebo.material</uri>
          </script>
          <diffuse>0.125 0.125 0.125 1</diffuse>
          <ambient>0.125 0.125 0.125 1</ambient>
        </material>
      </visual>
      <visual name='base_footprint_fixed_joint_lump__torso_fixed_link_visual_17'>
        <pose>-0.062 0 0.2915 0 0 0</pose>
        <geometry>
          <mesh>
            <scale>1 1 1</scale>
            <uri>meshes/torso/torso_fix.stl</uri>
          </mesh>
        </geometry>
        <material>
          <diffuse>1 1 1 1</diffuse>
          <ambient>1 1 1 1</ambient>
        </material>
      </visual>
      <visual name='base_footprint_fixed_joint_lump__base_cover_link_visual_18'>
        <pose>0 0 0.13 0 0 0</pose>
        <geometry>
          <mesh>
            <scale>1 1 1</scale>
            <uri>../../../../pmb2_robot/pmb2_description/meshes/base/base_ring.stl</uri>
          </mesh>
        </geometry>
        <material>
          <script>
            <name>Gazebo/Orange</name>
            <uri>file://media/materials/scripts/gazebo.material</uri>
          </script>
          <diffuse>1 0.60875 0 1</diffuse>
          <ambient>1 0.60875 0 1</ambient>
        </material>
      </visual>
      <sensor name='base_imu_sensor' type='imu'>
        <always_on>true</always_on>
        <update_rate>100</update_rate>
        <imu>
          <noise>
            <type>gaussian</type>
            <rate>
              <mean>0.0</mean>
              <stddev>2e-4</stddev>
              <bias_mean>0.0000075</bias_mean>
              <bias_stddev>0.0000008</bias_stddev>
            </rate>
            <accel>
              <mean>0.0</mean>
              <stddev>1.7e-2</stddev>
              <bias_mean>0.1</bias_mean>
              <bias_stddev>0.001</bias_stddev>
            </accel>
          </noise>
        </imu>
        <pose>0.10171 0 0.21132 0 0 -1.5708</pose>
      </sensor>
      <sensor name='base_laser' type='gpu_ray'>
        <update_rate>10</update_rate>
        <visualize>true</visualize>
        <ray>
          <scan>
            <horizontal>
              <samples>666</samples>
              <resolution>1</resolution>
              <min_angle>-1.9198621771937625</min_angle>
              <max_angle>1.9198621771937625</max_angle>
            </horizontal>
          </scan>
          <range>
            <min>0.050000000000000003</min>
            <max>25</max>
            <resolution>0.001</resolution>
          </range>
          <noise>
            <type>gaussian</type>
            <mean>0</mean>
            <stddev>0.01</stddev>
          </noise>
        </ray>
        <pose>0.202 0 0.0945 0 -0 0</pose>
      </sensor>
      <sensor name='base_sonar_01' type='gpu_ray'>
        <update_rate>5</update_rate>
        <visualize>false</visualize>
        <ray>
          <scan>
            <horizontal>
              <samples>5</samples>
              <resolution>1</resolution>
              <min_angle>-0.25</min_angle>
              <max_angle>0.25</max_angle>
            </horizontal>
            <vertical>
              <samples>5</samples>
              <resolution>1</resolution>
              <min_angle>-0.25</min_angle>
              <max_angle>0.25</max_angle>
            </vertical>
          </scan>
          <range>
            <min>0.02</min>
            <max>1</max>
            <resolution>0.01</resolution>
          </range>
          <noise>
            <type>gaussian</type>
            <mean>0</mean>
            <stddev>0.0050000000000000001</stddev>
          </noise>
        </ray>
        <pose>-0.183 -0.183 0.2715 0 0 -2.35619</pose>
      </sensor>
      <sensor name='base_sonar_02' type='gpu_ray'>
        <update_rate>5</update_rate>
        <visualize>false</visualize>
        <ray>
          <scan>
            <horizontal>
              <samples>5</samples>
              <resolution>1</resolution>
              <min_angle>-0.25</min_angle>
              <max_angle>0.25</max_angle>
            </horizontal>
            <vertical>
              <samples>5</samples>
              <resolution>1</resolution>
              <min_angle>-0.25</min_angle>
              <max_angle>0.25</max_angle>
            </vertical>
          </scan>
          <range>
            <min>0.02</min>
            <max>1</max>
            <resolution>0.01</resolution>
          </range>
          <noise>
            <type>gaussian</type>
            <mean>0</mean>
            <stddev>0.0050000000000000001</stddev>
          </noise>
        </ray>
        <pose>-0.259 0 0.2715 0 -0 3.14159</pose>
      </sensor>
      <sensor name='base_sonar_03' type='gpu_ray'>
        <update_rate>5</update_rate>
        <visualize>false</visualize>
        <ray>
          <scan>
            <horizontal>
              <samples>5</samples>
              <resolution>1</resolution>
              <min_angle>-0.25</min_angle>
              <max_angle>0.25</max_angle>
            </horizontal>
            <vertical>
              <samples>5</samples>
              <resolution>1</resolution>
              <min_angle>-0.25</min_angle>
              <max_angle>0.25</max_angle>
            </vertical>
          </scan>
          <range>
            <min>0.02</min>
            <max>1</max>
            <resolution>0.01</resolution>
          </range>
          <noise>
            <type>gaussian</type>
            <mean>0</mean>
            <stddev>0.0050000000000000001</stddev>
          </noise>
        </ray>
        <pose>-0.183 0.183 0.2715 0 -0 2.35619</pose>
      </sensor>
    </link>
    <joint name='wheel_left_joint' type='revolute'>
      <pose relative_to='base_footprint'>0 0.2022 0.0985 -1.570796326794896 0 0</pose>
      <parent>base_footprint</parent>
      <child>wheel_left_link</child>
      <axis>
        <xyz>0 0 1</xyz>
        <limit>
          <effort>6</effort>
          <velocity>100</velocity>
          <lower>-10000000000000000</lower>
          <upper>10000000000000000</upper>
        </limit>
        <dynamics>
          <damping>1</damping>
          <friction>2</friction>
          <spring_reference>0</spring_reference>
          <spring_stiffness>0</spring_stiffness>
        </dynamics>
      </axis>
    </joint>
    <link name='wheel_left_link'>
      <pose relative_to='wheel_left_joint'>0 0 0 0 0 0</pose>
      <inertial>
        <pose>0 0 0.00207 0 0 0</pose>
        <mass>1.82362</mass>
        <inertia>
          <ixx>0.0049974317099999999</ixx>
          <ixy>-4.4640000000000001e-08</ixy>
          <ixz>-2.2449999999999999e-08</ixz>
          <iyy>0.0049974173300000001</iyy>
          <iyz>1.6399999999999999e-09</iyz>
          <izz>0.0083923969199999997</izz>
        </inertia>
      </inertial>
      <collision name='wheel_left_link_collision'>
        <pose>0 0 0 0 0 0</pose>
        <geometry>
          <cylinder>
            <length>0.040000000000000001</length>
            <radius>0.098500000000000004</radius>
          </cylinder>
        </geometry>
        <surface>
          <contact>
            <ode>
              <kp>1000000</kp>
              <kd>100</kd>
              <max_vel>1</max_vel>
              <min_depth>0.002</min_depth>
            </ode>
          </contact>
          <friction>
            <ode>
              <mu>1</mu>
              <mu2>1</mu2>
            </ode>
          </friction>
        </surface>
      </collision>
      <visual name='wheel_left_link_visual'>
        <pose>0 0 0 -3.141592653589793 0 0</pose>
        <geometry>
          <mesh>
            <scale>1 1 1</scale>
            <uri>../../../../pmb2_robot/pmb2_description/meshes/wheels/wheel.stl</uri>
          </mesh>
        </geometry>
        <material>
          <script>
            <name>Gazebo/DarkGrey</name>
            <uri>file://media/materials/scripts/gazebo.material</uri>
          </script>
          <diffuse>0.125 0.125 0.125 1</diffuse>
          <ambient>0.125 0.125 0.125 1</ambient>
        </material>
      </visual>
    </link>
    <joint name='wheel_right_joint' type='revolute'>
      <pose relative_to='base_footprint'>0 -0.2022 0.0985 -1.570796326794896 0 0</pose>
      <parent>base_footprint</parent>
      <child>wheel_right_link</child>
      <axis>
        <xyz>0 0 1</xyz>
        <limit>
          <effort>6</effort>
          <velocity>100</velocity>
          <lower>-10000000000000000</lower>
          <upper>10000000000000000</upper>
        </limit>
        <dynamics>
          <damping>1</damping>
          <friction>2</friction>
          <spring_reference>0</spring_reference>
          <spring_stiffness>0</spring_stiffness>
        </dynamics>
      </axis>
    </joint>
    <link name='wheel_right_link'>
      <pose relative_to='wheel_right_joint'>0 0 0 0 0 0</pose>
      <inertial>
        <pose>0 0 -0.00207 0 0 0</pose>
        <mass>1.82362</mass>
        <inertia>
          <ixx>0.0049974317099999999</ixx>
          <ixy>4.4640000000000001e-08</ixy>
          <ixz>-2.2449999999999999e-08</ixz>
          <iyy>0.0049974173300000001</iyy>
          <iyz>-1.6399999999999999e-09</iyz>
          <izz>0.0083923969199999997</izz>
        </inertia>
      </inertial>
      <collision name='wheel_right_link_collision'>
        <pose>0 0 0 0 0 0</pose>
        <geometry>
          <cylinder>
            <length>0.040000000000000001</length>
            <radius>0.098500000000000004</radius>
          </cylinder>
        </geometry>
        <surface>
          <contact>
            <ode>
              <kp>1000000</kp>
              <kd>100</kd>
              <max_vel>1</max_vel>
              <min_depth>0.002</min_depth>
            </ode>
          </contact>
          <friction>
            <ode>
              <mu>1</mu>
              <mu2>1</mu2>
            </ode>
          </friction>
        </surface>
      </collision>
      <visual name='wheel_right_link_visual'>
        <pose>0 0 0 0 0 0</pose>
        <geometry>
          <mesh>
            <scale>1 1 1</scale>
            <uri>../../../../pmb2_robot/pmb2_description/meshes/wheels/wheel.stl</uri>
          </mesh>
        </geometry>
        <material>
          <script>
            <name>Gazebo/DarkGrey</name>
            <uri>file://media/materials/scripts/gazebo.material</uri>
          </script>
          <diffuse>0.125 0.125 0.125 1</diffuse>
          <ambient>0.125 0.125 0.125 1</ambient>
        </material>
      </visual>
    </link>
    <joint name='torso_lift_joint' type='prismatic'>
      <pose relative_to='base_footprint'>-0.062 0 0.8885000000000001 0 0 0</pose>
      <parent>base_footprint</parent>
      <child>torso_lift_link</child>
      <axis>
        <xyz>0 0 1</xyz>
        <limit>
          <lower>0</lower>
          <upper>0.34999999999999998</upper>
          <effort>2000</effort>
          <velocity>0.070000000000000007</velocity>
        </limit>
        <dynamics>
          <damping>1000</damping>
          <friction>0</friction>
          <spring_reference>0</spring_reference>
          <spring_stiffness>0</spring_stiffness>
        </dynamics>
      </axis>
    </joint>
    <link name='torso_lift_link'>
      <pose relative_to='torso_lift_joint'>0 0 0 0 0 0</pose>
      <inertial>
        <pose>0.04361 -0.00116 -0.17334 0 0 0</pose>
        <mass>6.9319800000000003</mass>
        <inertia>
          <ixx>0.24487</ixx>
          <ixy>-0.001456</ixy>
          <ixz>-0.0097420000000000007</ixz>
          <iyy>0.24926899999999999</iyy>
          <iyz>0.0082810000000000002</iyz>
          <izz>0.090395000000000003</izz>
        </inertia>
      </inertial>
      <collision name='torso_lift_link_collision'>
        <pose>0 0 0 0 0 0</pose>
        <geometry>
          <mesh>
            <scale>1 1 1</scale>
            <uri>meshes/torso/torso_lift_collision_core.dae</uri>
          </mesh>
        </geometry>
      </collision>
      <collision name='torso_lift_link_collision_1'>
        <pose>0 0 0 0 0 0</pose>
        <geometry>
          <mesh>
            <scale>1 1 1</scale>
            <uri>meshes/torso/torso_lift_collision_shoulder.dae</uri>
          </mesh>
        </geometry>
      </collision>
      <collision name='torso_lift_link_collision_2'>
        <pose>0 0 0 0 0 0</pose>
        <geometry>
          <mesh>
            <scale>1 1 1</scale>
            <uri>meshes/torso/torso_lift_collision_neck.dae</uri>
          </mesh>
        </geometry>
      </collision>
      <visual name='torso_lift_link_visual'>
        <pose>0 0 0 0 0 0</pose>
        <geometry>
          <mesh>
            <scale>1 1 1</scale>
            <uri>meshes/torso/torso_lift_with_arm.stl</uri>
          </mesh>
        </geometry>
        <material>
          <diffuse>1 1 1 1</diffuse>
          <ambient>1 1 1 1</ambient>
        </material>
      </visual>
    </link>
    <joint name='arm_1_joint' type='revolute'>
      <pose relative_to='torso_lift_link'>0.15505 0.014 -0.151 0 0 -1.570796326794896</pose>
      <parent>torso_lift_link</parent>
      <child>arm_1_link</child>
      <axis>
        <xyz>0 0 1</xyz>
        <limit>
          <lower>0</lower>
          <upper>2.748893571891069</upper>
          <effort>43</effort>
          <velocity>1.95</velocity>
        </limit>
        <dynamics>
          <damping>40</damping>
          <friction>1</friction>
          <spring_reference>0</spring_reference>
          <spring_stiffness>0</spring_stiffness>
        </dynamics>
      </axis>
      <physics>
        <ode>
          <implicit_spring_damper>true</implicit_spring_damper>
          <cfm_damping>true</cfm_damping>
          <limit>
            <cfm>0</cfm>
            <erp>0.20000000000000001</erp>
          </limit>
        </ode>
      </physics>
    </joint>
    <link name='arm_1_link'>
      <pose relative_to='arm_1_joint'>0 0 0 0 0 0</pose>
      <inertial>
        <pose>0.061191 -0.022397 -0.012835 0 0 0</pose>
        <mass>1.56</mass>
        <inertia>
          <!-- Manually adjusted to be positive definite and axis-aligned -->
          <ixx>0.01</ixx>
          <ixy>0</ixy>
          <ixz>0</ixz>
          <iyy>0.01</iyy>
          <iyz>0</iyz>
          <izz>0.01</izz>
        </inertia>
      </inertial>
      <collision name='arm_1_link_collision'>
        <pose>0 0 0 0 0 0</pose>
        <geometry>
          <mesh>
            <scale>1 1 1</scale>
            <uri>meshes/arm/arm_1_collision.dae</uri>
          </mesh>
        </geometry>
        <surface>
          <contact>
            <ode/>
          </contact>
          <friction>
            <ode>
              <mu>0.90000000000000002</mu>
              <mu2>0.90000000000000002</mu2>
            </ode>
          </friction>
        </surface>
      </collision>
      <visual name='arm_1_link_visual'>
        <pose>0 0 0 0 0 0</pose>
        <geometry>
          <mesh>
            <scale>1 1 1</scale>
            <uri>meshes/arm/arm_1.stl</uri>
          </mesh>
        </geometry>
        <material>
          <script>
            <name>Gazebo/DarkGrey</name>
            <uri>file://media/materials/scripts/gazebo.material</uri>
          </script>
          <diffuse>1 1 1 1</diffuse>
          <ambient>1 1 1 1</ambient>
        </material>
      </visual>
    </link>
    <joint name='arm_2_joint' type='revolute'>
      <pose relative_to='arm_1_link'>0.125 0.0195 -0.031 1.570796326794896 0 0</pose>
      <parent>arm_1_link</parent>
      <child>arm_2_link</child>
      <axis>
        <xyz>0 0 1</xyz>
        <limit>
          <lower>-1.570796326794897</lower>
          <upper>1.090830782496456</upper>
          <effort>43</effort>
          <velocity>1.95</velocity>
        </limit>
        <dynamics>
          <damping>40</damping>
          <friction>1</friction>
          <spring_reference>0</spring_reference>
          <spring_stiffness>0</spring_stiffness>
        </dynamics>
      </axis>
      <physics>
        <ode>
          <implicit_spring_damper>true</implicit_spring_damper>
          <cfm_damping>true</cfm_damping>
          <limit>
            <cfm>0</cfm>
            <erp>0.20000000000000001</erp>
          </limit>
        </ode>
      </physics>
    </joint>
    <link name='arm_2_link'>
      <pose relative_to='arm_2_joint'>0 0 0 0 0 0</pose>
      <inertial>
        <pose>0.030432 0.000229 -0.005942 0 0 0</pose>
        <mass>1.800397</mass>
        <inertia>
          <ixx>0.0018090000000000001</ixx>
          <ixy>1.5e-05</ixy>
          <ixz>0.00025399999999999999</ixz>
          <iyy>0.004333</iyy>
          <iyz>1.4e-05</iyz>
          <izz>0.0043410000000000002</izz>
        </inertia>
      </inertial>
      <collision name='arm_2_link_collision'>
        <pose>0 0 0 0 0 0</pose>
        <geometry>
          <mesh>
            <scale>1 1 1</scale>
            <uri>meshes/arm/arm_2_collision.dae</uri>
          </mesh>
        </geometry>
        <surface>
          <contact>
            <ode/>
          </contact>
          <friction>
            <ode>
              <mu>0.90000000000000002</mu>
              <mu2>0.90000000000000002</mu2>
            </ode>
          </friction>
        </surface>
      </collision>
      <visual name='arm_2_link_visual'>
        <pose>0 0 0 0 0 0</pose>
        <geometry>
          <mesh>
            <scale>1 1 1</scale>
            <uri>meshes/arm/arm_2.stl</uri>
          </mesh>
        </geometry>
        <material>
          <script>
            <name>Gazebo/DarkGrey</name>
            <uri>file://media/materials/scripts/gazebo.material</uri>
          </script>
          <diffuse>0.125 0.125 0.125 1</diffuse>
          <ambient>0.125 0.125 0.125 1</ambient>
        </material>
      </visual>
    </link>
    <joint name='arm_3_joint' type='revolute'>
      <pose relative_to='arm_2_link'>0.0895 0 -0.0015 -1.570796326794896 0 1.570796326794896</pose>
      <parent>arm_2_link</parent>
      <child>arm_3_link</child>
      <axis>
        <xyz>0 0 1</xyz>
        <limit>
          <lower>-3.5342917352885168</lower>
          <upper>1.570796326794897</upper>
          <effort>26</effort>
          <velocity>2.3500000000000001</velocity>
        </limit>
        <dynamics>
          <damping>40</damping>
          <friction>1</friction>
          <spring_reference>0</spring_reference>
          <spring_stiffness>0</spring_stiffness>
        </dynamics>
      </axis>
      <physics>
        <ode>
          <implicit_spring_damper>true</implicit_spring_damper>
          <cfm_damping>true</cfm_damping>
          <limit>
            <cfm>0</cfm>
            <erp>0.20000000000000001</erp>
          </limit>
        </ode>
      </physics>
    </joint>
    <link name='arm_3_link'>
      <pose relative_to='arm_3_joint'>0 0 0 0 0 0</pose>
      <inertial>
        <pose>0.007418 -0.004361 -0.134194 0 0 0</pose>
        <mass>1.8</mass>
        <inertia>
          <ixx>0.019540999999999999</ixx>
          <ixy>-0.000105</ixy>
          <ixz>-0.001717</ixz>
          <iyy>0.019935999999999999</iyy>
          <iyz>0.000852</iyz>
          <izz>0.0028639999999999998</izz>
        </inertia>
      </inertial>
      <collision name='arm_3_link_collision'>
        <pose>0 0 0 0 0 0</pose>
        <geometry>
          <mesh>
            <scale>1 1 1</scale>
            <uri>meshes/arm/arm_3_collision.dae</uri>
          </mesh>
        </geometry>
        <surface>
          <contact>
            <ode/>
          </contact>
          <friction>
            <ode>
              <mu>0.90000000000000002</mu>
              <mu2>0.90000000000000002</mu2>
            </ode>
          </friction>
        </surface>
      </collision>
      <visual name='arm_3_link_visual'>
        <pose>0 0 0 0 0 0</pose>
        <geometry>
          <mesh>
            <scale>1 1 1</scale>
            <uri>meshes/arm/arm_3.stl</uri>
          </mesh>
        </geometry>
        <material>
          <script>
            <name>Gazebo/DarkGrey</name>
            <uri>file://media/materials/scripts/gazebo.material</uri>
          </script>
          <diffuse>0.125 0.125 0.125 1</diffuse>
          <ambient>0.125 0.125 0.125 1</ambient>
        </material>
      </visual>
    </link>
    <joint name='arm_4_joint' type='revolute'>
      <pose relative_to='arm_3_link'>-0.02 -0.027 -0.222 -1.570796326794896 -1.570796326794897 0</pose>
      <parent>arm_3_link</parent>
      <child>arm_4_link</child>
      <axis>
        <xyz>0 0 1</xyz>
        <limit>
          <lower>-0.39269908169872408</lower>
          <upper>2.3561944901923448</upper>
          <effort>26</effort>
          <velocity>2.3500000000000001</velocity>
        </limit>
        <dynamics>
          <damping>40</damping>
          <friction>1</friction>
          <spring_reference>0</spring_reference>
          <spring_stiffness>0</spring_stiffness>
        </dynamics>
      </axis>
      <physics>
        <ode>
          <implicit_spring_damper>true</implicit_spring_damper>
          <cfm_damping>true</cfm_damping>
          <limit>
            <cfm>0</cfm>
            <erp>0.20000000000000001</erp>
          </limit>
        </ode>
      </physics>
    </joint>
    <link name='arm_4_link'>
      <pose relative_to='arm_4_joint'>0 0 0 0 0 0</pose>
      <inertial>
        <pose>-0.09565800000000001 0.014666 0.018133 0 0 0</pose>
        <mass>1.4326970000000001</mass>
        <inertia>
          <ixx>0.0020400000000000001</ixx>
          <ixy>0.00072499999999999995</ixy>
          <ixz>-0.00115</ixz>
          <iyy>0.0084239999999999992</iyy>
          <iyz>-0.000204</iyz>
          <izz>0.0086859999999999993</izz>
        </inertia>
      </inertial>
      <collision name='arm_4_link_collision'>
        <pose>0 0 0 0 0 0</pose>
        <geometry>
          <mesh>
            <scale>1 1 1</scale>
            <uri>meshes/arm/arm_4_collision.dae</uri>
          </mesh>
        </geometry>
        <surface>
          <contact>
            <ode/>
          </contact>
          <friction>
            <ode>
              <mu>0.90000000000000002</mu>
              <mu2>0.90000000000000002</mu2>
            </ode>
          </friction>
        </surface>
      </collision>
      <visual name='arm_4_link_visual'>
        <pose>0 0 0 0 0 0</pose>
        <geometry>
          <mesh>
            <scale>1 1 1</scale>
            <uri>meshes/arm/arm_4.stl</uri>
          </mesh>
        </geometry>
        <material>
          <script>
            <name>Gazebo/DarkGrey</name>
            <uri>file://media/materials/scripts/gazebo.material</uri>
          </script>
          <diffuse>0.125 0.125 0.125 1</diffuse>
          <ambient>0.125 0.125 0.125 1</ambient>
        </material>
      </visual>
    </link>
    <joint name='arm_5_joint' type='revolute'>
      <pose relative_to='arm_4_link'>-0.162 0.02 0.027 0 -1.570796326794897 0</pose>
      <parent>arm_4_link</parent>
      <child>arm_5_link</child>
      <axis>
        <xyz>0 0 1</xyz>
        <limit>
          <lower>-2.0943951023931948</lower>
          <upper>2.0943951023931948</upper>
          <effort>3</effort>
          <velocity>1.95</velocity>
        </limit>
        <dynamics>
          <damping>1</damping>
          <friction>1</friction>
          <spring_reference>0</spring_reference>
          <spring_stiffness>0</spring_stiffness>
        </dynamics>
      </axis>
      <physics>
        <ode>
          <implicit_spring_damper>true</implicit_spring_damper>
          <cfm_damping>true</cfm_damping>
          <limit>
            <cfm>0</cfm>
            <erp>0.20000000000000001</erp>
          </limit>
        </ode>
      </physics>
    </joint>
    <link name='arm_5_link'>
      <pose relative_to='arm_5_joint'>0 0 0 0 0 0</pose>
      <inertial>
        <pose>0.001078 -0.000151 -0.07717300000000001 0 0 0</pose>
        <mass>0.93591436890000002</mass>
        <inertia>
          <ixx>0.001036187977</ixx>
          <ixy>1.0622321000000001e-07</ixy>
          <ixz>1.9920336000000001e-06</ixz>
          <iyy>0.00079452717636609605</iyy>
          <iyz>-2.5639610699840398e-07</iyz>
          <izz>0.00043983122997917802</izz>
        </inertia>
      </inertial>
      <collision name='arm_5_link_collision'>
        <pose>0 0 0 0 0 0</pose>
        <geometry>
          <mesh>
            <scale>1 1 1</scale>
            <uri>meshes/arm/arm_5_collision-wrist-2017.dae</uri>
          </mesh>
        </geometry>
        <surface>
          <contact>
            <ode/>
          </contact>
          <friction>
            <ode>
              <mu>0.90000000000000002</mu>
              <mu2>0.90000000000000002</mu2>
            </ode>
          </friction>
        </surface>
      </collision>
      <visual name='arm_5_link_visual'>
        <pose>0 0 0 0 0 0</pose>
        <geometry>
          <mesh>
            <scale>1 1 1</scale>
            <uri>meshes/arm/arm_5-wrist-2017.stl</uri>
          </mesh>
        </geometry>
        <material>
          <diffuse>1 1 1 1</diffuse>
          <ambient>1 1 1 1</ambient>
        </material>
      </visual>
    </link>
    <joint name='arm_6_joint' type='revolute'>
      <pose relative_to='arm_5_link'>0 0 0.15 -1.570796326794896 -1.570796326794897 0</pose>
      <parent>arm_5_link</parent>
      <child>arm_6_link</child>
      <axis>
        <xyz>0 0 1</xyz>
        <limit>
          <lower>-1.4137166941154069</lower>
          <upper>1.4137166941154069</upper>
          <effort>6.5999999999999996</effort>
          <velocity>1.76</velocity>
        </limit>
        <dynamics>
          <damping>1</damping>
          <friction>1</friction>
          <spring_reference>0</spring_reference>
          <spring_stiffness>0</spring_stiffness>
        </dynamics>
      </axis>
      <physics>
        <ode>
          <implicit_spring_damper>true</implicit_spring_damper>
          <cfm_damping>true</cfm_damping>
          <limit>
            <cfm>0</cfm>
            <erp>0.20000000000000001</erp>
          </limit>
        </ode>
      </physics>
    </joint>
    <link name='arm_6_link'>
      <pose relative_to='arm_6_joint'>0 0 0 0 0 0</pose>
      <inertial>
        <pose>-0.000153 -0.003122 0.000183 0 0 0</pose>
        <mass>0.30275767222</mass>
        <inertia>
          <ixx>3.2923355700000002e-05</ixx>
          <ixy>6.3153739500000006e-08</ixy>
          <ixz>-4.5671249120000002e-11</ixz>
          <iyy>3.85334410118923e-05</iyy>
          <iyz>-2.01613082836742e-07</iyz>
          <izz>3.3328284916803898e-05</izz>
        </inertia>
      </inertial>
      <collision name='arm_6_link_collision'>
        <pose>0 0 0 0 0 0</pose>
        <geometry>
          <mesh>
            <scale>1 1 1</scale>
            <uri>meshes/arm/arm_6_collision-wrist-2017.dae</uri>
          </mesh>
        </geometry>
        <surface>
          <contact>
            <ode/>
          </contact>
          <friction>
            <ode>
              <mu>0.90000000000000002</mu>
              <mu2>0.90000000000000002</mu2>
            </ode>
          </friction>
        </surface>
      </collision>
      <visual name='arm_6_link_visual'>
        <pose>0 0 0 0 0 0</pose>
        <geometry>
          <mesh>
            <scale>1 1 1</scale>
            <uri>meshes/arm/arm_6-wrist-2017.stl</uri>
          </mesh>
        </geometry>
        <material>
          <diffuse>1 1 1 1</diffuse>
          <ambient>1 1 1 1</ambient>
        </material>
      </visual>
    </link>
    <joint name='arm_7_joint' type='revolute'>
      <pose relative_to='arm_6_link'>0 0 0 1.570796326794896 0 1.570796326794896</pose>
      <parent>arm_6_link</parent>
      <child>arm_7_link</child>
      <axis>
        <xyz>0 0 1</xyz>
        <limit>
          <lower>-2.0943951023931948</lower>
          <upper>2.0943951023931948</upper>
          <effort>6.5999999999999996</effort>
          <velocity>1.76</velocity>
        </limit>
        <dynamics>
          <damping>1</damping>
          <friction>1</friction>
          <spring_reference>0</spring_reference>
          <spring_stiffness>0</spring_stiffness>
        </dynamics>
      </axis>
      <physics>
        <provide_feedback>true</provide_feedback>
        <ode>
          <implicit_spring_damper>true</implicit_spring_damper>
          <cfm_damping>true</cfm_damping>
          <limit>
            <cfm>0</cfm>
            <erp>0.20000000000000001</erp>
          </limit>
          <provide_feedback>true</provide_feedback>
        </ode>
      </physics>
    </joint>
    <link name='arm_7_link'>
      <pose relative_to='arm_7_joint'>0 0 0 0 0 0</pose>
      <inertial>
        <pose>5.000000000000001e-06 -1.5e-06 0.0220505 0 0 0</pose>
        <mass>0.20000000000000001</mass>
        <inertia>
          <ixx>0.00018939614</ixx>
          <ixy>-1.390712219e-07</ixy>
          <ixz>3.5754707406000012e-08</ixz>
          <iyy>0.0001892595734740734</iyy>
          <iyz>-2.6786976081252799e-08</iyz>
          <izz>2.0189903930404801e-05</izz>
        </inertia>
      </inertial>
      <collision name='arm_7_link_fixed_joint_lump__arm_tool_link_collision'>
        <pose>-4.336808689942018e-19 0 0.052875 2.355138688025663e-16 -7.850462293418872e-17 -1.570796326794897</pose>
        <geometry>
          <cylinder>
            <length>0.0050000000000000001</length>
            <radius>0.0050000000000000001</radius>
          </cylinder>
        </geometry>
      </collision>
      <visual name='arm_7_link_fixed_joint_lump__arm_tool_link_visual'>
        <pose>-4.336808689942018e-19 0 0.052875 2.355138688025663e-16 -7.850462293418872e-17 -1.570796326794897</pose>
        <geometry>
          <cylinder>
            <length>0.0050000000000000001</length>
            <radius>0.0050000000000000001</radius>
          </cylinder>
        </geometry>
        <material>
          <diffuse>1 1 1 1</diffuse>
          <ambient>1 1 1 1</ambient>
        </material>
      </visual>
    </link>
    <joint name='wrist_ft_joint' type='fixed'>
      <pose relative_to='arm_7_link'>0 0 0.051875 2.355138688025663e-16 -7.850462293418872e-17 -1.570796326794897</pose>
      <parent>arm_7_link</parent>
      <child>wrist_ft_link</child>
      <axis>
        <dynamics>
          <spring_reference>0</spring_reference>
          <spring_stiffness>0</spring_stiffness>
        </dynamics>
        <xyz>0 0 1</xyz>
        <limit>
          <lower>-10000000000000000</lower>
          <upper>10000000000000000</upper>
        </limit>
      </axis>
      <physics>
        <ode>
          <limit>
            <cfm>0</cfm>
            <erp>0.20000000000000001</erp>
          </limit>
        </ode>
      </physics>
      <sensor name='wrist_ft_sensor' type='force_torque'>
        <update_rate>100</update_rate>
        <visualize>true</visualize>
        <force_torque>
          <frame>child</frame>
          <measure_direction>child_to_parent</measure_direction>
        </force_torque>
      </sensor>
    </joint>
    <link name='wrist_ft_link'>
      <pose relative_to='wrist_ft_joint'>0 0 0 0 0 0</pose>
      <inertial>
        <pose>-0.00141176470588235 -0.001478991596638656 0.05250420168067228 0 0 0</pose>
        <mass>0.59499999999999997</mass>
        <inertia>
          <ixx>0.001312834226890757</ixx>
          <ixy>-9.2276470588235276e-06</ixy>
          <ixz>3.8464705882352456e-06</ixz>
          <iyy>0.001467846857142857</iyy>
          <iyz>2.5097302521008411e-05</iyz>
          <izz>0.00033331260504201681</izz>
        </inertia>
      </inertial>
      <collision name='wrist_ft_link_collision'>
        <pose>0 0 0 0 0 0</pose>
        <geometry>
          <cylinder>
            <length>0.015699999999999999</length>
            <radius>0.022499999999999999</radius>
          </cylinder>
        </geometry>
      </collision>
      <collision name='wrist_ft_link_fixed_joint_lump__wrist_ft_tool_link_collision_1'>
        <pose>0 0 0.0112 0 0 0</pose>
        <geometry>
          <cylinder>
            <length>0.00975</length>
            <radius>0.025000000000000001</radius>
          </cylinder>
        </geometry>
      </collision>
      <collision name='wrist_ft_link_fixed_joint_lump__hand_palm_link_collision_2'>
        <pose>0 0 0.0112 0 -1.570796326794897 0</pose>
        <geometry>
          <mesh>
            <scale>1 1 1</scale>
            <uri>../../../../pal_hey5/pal_hey5_description/meshes/palm_collision.stl</uri>
          </mesh>
        </geometry>
        <surface>
          <contact>
            <ode/>
          </contact>
          <friction>
            <ode/>
          </friction>
        </surface>
      </collision>
      <collision name='wrist_ft_link_fixed_joint_lump__hand_safety_box_collision_3'>
        <pose>-0.01999999999999999 0.02 0.1112 0 -1.570796326794897 0</pose>
        <geometry>
          <box>
            <size>0.2 0.115 0.18</size>
          </box>
        </geometry>
      </collision>
      <visual name='wrist_ft_link_visual'>
        <pose>0 0 0 0 0 0</pose>
        <geometry>
          <cylinder>
            <length>0.015699999999999999</length>
            <radius>0.022499999999999999</radius>
          </cylinder>
        </geometry>
        <material>
          <diffuse>1 1 1 1</diffuse>
          <ambient>1 1 1 1</ambient>
        </material>
      </visual>
      <visual name='wrist_ft_link_fixed_joint_lump__wrist_ft_tool_link_visual_1'>
        <pose>0 0 0.0112 0 0 0</pose>
        <geometry>
          <cylinder>
            <length>0.00975</length>
            <radius>0.025000000000000001</radius>
          </cylinder>
        </geometry>
        <material>
          <diffuse>0.1125 0.1125 0.1125 1</diffuse>
          <ambient>0.1125 0.1125 0.1125 1</ambient>
        </material>
      </visual>
      <visual name='wrist_ft_link_fixed_joint_lump__hand_palm_link_visual_2'>
        <pose>0 0 0.0112 0 -1.570796326794897 0</pose>
        <geometry>
          <mesh>
            <scale>1 1 1</scale>
            <uri>../../../../pal_hey5/pal_hey5_description/meshes/palm.stl</uri>
          </mesh>
        </geometry>
        <material>
          <script>
            <name>Gazebo/Black</name>
            <uri>file://media/materials/scripts/gazebo.material</uri>
          </script>
          <diffuse>0.125 0.125 0.125 1</diffuse>
          <ambient>0.125 0.125 0.125 1</ambient>
        </material>
      </visual>
    </link>
    <joint name='hand_index_abd_joint' type='revolute'>
      <pose relative_to='wrist_ft_link'>-0.02649999999999997 0.0042 0.1377 1.570796326794897 -1.047197551196598 3.141592653589793</pose>
      <parent>wrist_ft_link</parent>
      <child>hand_index_abd_link</child>
      <axis>
        <xyz>0 0 1</xyz>
        <limit>
          <lower>-0.52359877559829882</lower>
          <upper>0.52359877559829882</upper>
          <effort>2</effort>
          <velocity>2</velocity>
        </limit>
        <dynamics>
          <damping>0.5</damping>
          <friction>0</friction>
          <spring_reference>0</spring_reference>
          <spring_stiffness>0</spring_stiffness>
        </dynamics>
      </axis>
    </joint>
    <link name='hand_index_abd_link'>
      <pose relative_to='hand_index_abd_joint'>0 0 0 0 0 0</pose>
      <inertial>
        <pose>-0.0018 0 0.0028 0 0 0</pose>
        <mass>0.017999999999999999</mass>
        <inertia>
          <ixx>0.001</ixx>
          <ixy>0</ixy>
          <ixz>0</ixz>
          <iyy>0.001</iyy>
          <iyz>0</iyz>
          <izz>0.001</izz>
        </inertia>
      </inertial>
      <collision name='hand_index_abd_link_collision'>
        <pose>0 0 0 0 0 0</pose>
        <geometry>
          <mesh>
            <scale>1 1 1</scale>
            <uri>../../../../pal_hey5/pal_hey5_description/meshes/finger_abd_collision.stl</uri>
          </mesh>
        </geometry>
        <surface>
          <contact>
            <ode/>
          </contact>
          <friction>
            <ode/>
          </friction>
        </surface>
      </collision>
      <visual name='hand_index_abd_link_visual'>
        <pose>0 0 0 0 0 0</pose>
        <geometry>
          <mesh>
            <scale>1 1 1</scale>
            <uri>../../../../pal_hey5/pal_hey5_description/meshes/finger_abd_collision.stl</uri>
          </mesh>
        </geometry>
        <material>
          <script>
            <name>Gazebo/Black</name>
            <uri>file://media/materials/scripts/gazebo.material</uri>
          </script>
          <diffuse>0.125 0.125 0.125 1</diffuse>
          <ambient>0.125 0.125 0.125 1</ambient>
        </material>
      </visual>
    </link>
    <joint name='hand_index_virtual_1_joint' type='revolute'>
      <pose relative_to='hand_index_abd_link'>0.008999999999999999 0 0 1.570796326794896 0 0</pose>
      <parent>hand_index_abd_link</parent>
      <child>hand_index_virtual_1_link</child>
      <axis>
        <xyz>0 0 1</xyz>
        <limit>
          <lower>0</lower>
          <upper>0.78539816339744828</upper>
          <effort>2</effort>
          <velocity>2</velocity>
        </limit>
        <dynamics>
          <damping>0.5</damping>
          <friction>0</friction>
          <spring_reference>0</spring_reference>
          <spring_stiffness>0</spring_stiffness>
        </dynamics>
      </axis>
    </joint>
    <link name='hand_index_virtual_1_link'>
      <pose relative_to='hand_index_virtual_1_joint'>0 0 0 0 0 0</pose>
      <inertial>
        <pose>0.0065 0 0 0 0 0</pose>
        <mass>0.01</mass>
        <inertia>
          <ixx>0.001</ixx>
          <ixy>0</ixy>
          <ixz>0</ixz>
          <iyy>0.001</iyy>
          <iyz>0</iyz>
          <izz>0.001</izz>
        </inertia>
      </inertial>
      <collision name='hand_index_virtual_1_link_collision'>
        <pose>0 0 0 0 0 0</pose>
        <geometry>
          <box>
            <size>0.013 0.002 0.012</size>
          </box>
        </geometry>
        <surface>
          <contact>
            <ode/>
          </contact>
          <friction>
            <ode/>
          </friction>
        </surface>
      </collision>
      <visual name='hand_index_virtual_1_link_visual'>
        <pose>0.0065 0 0 0 0 0</pose>
        <geometry>
          <box>
            <size>0.013 0.002 0.012</size>
          </box>
        </geometry>
        <material>
          <script>
            <name>Gazebo/Black</name>
            <uri>file://media/materials/scripts/gazebo.material</uri>
          </script>
          <diffuse>0.125 0.125 0.125 1</diffuse>
          <ambient>0.125 0.125 0.125 1</ambient>
        </material>
      </visual>
    </link>
    <joint name='hand_index_flex_1_joint' type='revolute'>
      <pose relative_to='hand_index_virtual_1_link'>0.013 0 0 0 0 0</pose>
      <parent>hand_index_virtual_1_link</parent>
      <child>hand_index_flex_1_link</child>
      <axis>
        <xyz>0 0 1</xyz>
        <limit>
          <lower>0</lower>
          <upper>0.78539816339744828</upper>
          <effort>2</effort>
          <velocity>2</velocity>
        </limit>
        <dynamics>
          <damping>0.5</damping>
          <friction>0</friction>
          <spring_reference>0</spring_reference>
          <spring_stiffness>0</spring_stiffness>
        </dynamics>
      </axis>
    </joint>
    <link name='hand_index_flex_1_link'>
      <pose relative_to='hand_index_flex_1_joint'>0 0 0 0 0 0</pose>
      <inertial>
        <pose>0.0047 0.0031 0 0 0 0</pose>
        <mass>0.0089999999999999993</mass>
        <inertia>
          <ixx>0.001</ixx>
          <ixy>0</ixy>
          <ixz>0</ixz>
          <iyy>0.001</iyy>
          <iyz>0</iyz>
          <izz>0.001</izz>
        </inertia>
      </inertial>
      <collision name='hand_index_flex_1_link_collision'>
        <pose>0 0 0 0 0 0</pose>
        <geometry>
          <mesh>
            <scale>1 1 1</scale>
            <uri>../../../../pal_hey5/pal_hey5_description/meshes/finger_flex_collision.stl</uri>
          </mesh>
        </geometry>
        <surface>
          <contact>
            <ode/>
          </contact>
          <friction>
            <ode/>
          </friction>
        </surface>
      </collision>
      <visual name='hand_index_flex_1_link_visual'>
        <pose>0 0 0 0 0 0</pose>
        <geometry>
          <mesh>
            <scale>1 1 1</scale>
            <uri>../../../../pal_hey5/pal_hey5_description/meshes/finger_flex_collision.stl</uri>
          </mesh>
        </geometry>
        <material>
          <script>
            <name>Gazebo/Black</name>
            <uri>file://media/materials/scripts/gazebo.material</uri>
          </script>
          <diffuse>0.125 0.125 0.125 1</diffuse>
          <ambient>0.125 0.125 0.125 1</ambient>
        </material>
      </visual>
    </link>
    <joint name='hand_index_virtual_2_joint' type='revolute'>
      <pose relative_to='hand_index_flex_1_link'>0.008999999999999999 0 0 0 0 0</pose>
      <parent>hand_index_flex_1_link</parent>
      <child>hand_index_virtual_2_link</child>
      <axis>
        <xyz>0 0 1</xyz>
        <limit>
          <lower>0</lower>
          <upper>0.78539816339744828</upper>
          <effort>2</effort>
          <velocity>2</velocity>
        </limit>
        <dynamics>
          <damping>0.5</damping>
          <friction>0</friction>
          <spring_reference>0</spring_reference>
          <spring_stiffness>0</spring_stiffness>
        </dynamics>
      </axis>
    </joint>
    <link name='hand_index_virtual_2_link'>
      <pose relative_to='hand_index_virtual_2_joint'>0 0 0 0 0 0</pose>
      <inertial>
        <pose>0.0065 0 0 0 0 0</pose>
        <mass>0.01</mass>
        <inertia>
          <ixx>0.001</ixx>
          <ixy>0</ixy>
          <ixz>0</ixz>
          <iyy>0.001</iyy>
          <iyz>0</iyz>
          <izz>0.001</izz>
        </inertia>
      </inertial>
      <collision name='hand_index_virtual_2_link_collision'>
        <pose>0 0 0 0 0 0</pose>
        <geometry>
          <box>
            <size>0.013 0.002 0.012</size>
          </box>
        </geometry>
        <surface>
          <contact>
            <ode/>
          </contact>
          <friction>
            <ode/>
          </friction>
        </surface>
      </collision>
      <visual name='hand_index_virtual_2_link_visual'>
        <pose>0.0065 0 0 0 0 0</pose>
        <geometry>
          <box>
            <size>0.013 0.002 0.012</size>
          </box>
        </geometry>
        <material>
          <script>
            <name>Gazebo/Black</name>
            <uri>file://media/materials/scripts/gazebo.material</uri>
          </script>
          <diffuse>0.125 0.125 0.125 1</diffuse>
          <ambient>0.125 0.125 0.125 1</ambient>
        </material>
      </visual>
    </link>
    <joint name='hand_index_flex_2_joint' type='revolute'>
      <pose relative_to='hand_index_virtual_2_link'>0.013 0 0 0 0 0</pose>
      <parent>hand_index_virtual_2_link</parent>
      <child>hand_index_flex_2_link</child>
      <axis>
        <xyz>0 0 1</xyz>
        <limit>
          <lower>0</lower>
          <upper>0.78539816339744828</upper>
          <effort>2</effort>
          <velocity>2</velocity>
        </limit>
        <dynamics>
          <damping>0.5</damping>
          <friction>0</friction>
          <spring_reference>0</spring_reference>
          <spring_stiffness>0</spring_stiffness>
        </dynamics>
      </axis>
    </joint>
    <link name='hand_index_flex_2_link'>
      <pose relative_to='hand_index_flex_2_joint'>0 0 0 0 0 0</pose>
      <inertial>
        <pose>0.0047 0.0031 0 0 0 0</pose>
        <mass>0.0089999999999999993</mass>
        <inertia>
          <ixx>0.001</ixx>
          <ixy>0</ixy>
          <ixz>0</ixz>
          <iyy>0.001</iyy>
          <iyz>0</iyz>
          <izz>0.001</izz>
        </inertia>
      </inertial>
      <collision name='hand_index_flex_2_link_collision'>
        <pose>0 0 0 0 0 0</pose>
        <geometry>
          <mesh>
            <scale>1 1 1</scale>
            <uri>../../../../pal_hey5/pal_hey5_description/meshes/finger_flex_collision.stl</uri>
          </mesh>
        </geometry>
        <surface>
          <contact>
            <ode/>
          </contact>
          <friction>
            <ode/>
          </friction>
        </surface>
      </collision>
      <visual name='hand_index_flex_2_link_visual'>
        <pose>0 0 0 0 0 0</pose>
        <geometry>
          <mesh>
            <scale>1 1 1</scale>
            <uri>../../../../pal_hey5/pal_hey5_description/meshes/finger_flex_collision.stl</uri>
          </mesh>
        </geometry>
        <material>
          <script>
            <name>Gazebo/Black</name>
            <uri>file://media/materials/scripts/gazebo.material</uri>
          </script>
          <diffuse>0.125 0.125 0.125 1</diffuse>
          <ambient>0.125 0.125 0.125 1</ambient>
        </material>
      </visual>
    </link>
    <joint name='hand_index_virtual_3_joint' type='revolute'>
      <pose relative_to='hand_index_flex_2_link'>0.008999999999999999 0 0 0 0 0</pose>
      <parent>hand_index_flex_2_link</parent>
      <child>hand_index_virtual_3_link</child>
      <axis>
        <xyz>0 0 1</xyz>
        <limit>
          <lower>0</lower>
          <upper>0.78539816339744828</upper>
          <effort>2</effort>
          <velocity>2</velocity>
        </limit>
        <dynamics>
          <damping>0.5</damping>
          <friction>0</friction>
          <spring_reference>0</spring_reference>
          <spring_stiffness>0</spring_stiffness>
        </dynamics>
      </axis>
    </joint>
    <link name='hand_index_virtual_3_link'>
      <pose relative_to='hand_index_virtual_3_joint'>0 0 0 0 0 0</pose>
      <inertial>
        <pose>0.0065 0 0 0 0 0</pose>
        <mass>0.01</mass>
        <inertia>
          <ixx>0.001</ixx>
          <ixy>0</ixy>
          <ixz>0</ixz>
          <iyy>0.001</iyy>
          <iyz>0</iyz>
          <izz>0.001</izz>
        </inertia>
      </inertial>
      <collision name='hand_index_virtual_3_link_collision'>
        <pose>0 0 0 0 0 0</pose>
        <geometry>
          <box>
            <size>0.013 0.002 0.012</size>
          </box>
        </geometry>
        <surface>
          <contact>
            <ode/>
          </contact>
          <friction>
            <ode/>
          </friction>
        </surface>
      </collision>
      <visual name='hand_index_virtual_3_link_visual'>
        <pose>0.0065 0 0 0 0 0</pose>
        <geometry>
          <box>
            <size>0.013 0.002 0.012</size>
          </box>
        </geometry>
        <material>
          <script>
            <name>Gazebo/Black</name>
            <uri>file://media/materials/scripts/gazebo.material</uri>
          </script>
          <diffuse>0.125 0.125 0.125 1</diffuse>
          <ambient>0.125 0.125 0.125 1</ambient>
        </material>
      </visual>
    </link>
    <joint name='hand_index_flex_3_joint' type='revolute'>
      <pose relative_to='hand_index_virtual_3_link'>0.013 0 0 0 0 0</pose>
      <parent>hand_index_virtual_3_link</parent>
      <child>hand_index_flex_3_link</child>
      <axis>
        <xyz>0 0 1</xyz>
        <limit>
          <lower>0</lower>
          <upper>0.78539816339744828</upper>
          <effort>2</effort>
          <velocity>2</velocity>
        </limit>
        <dynamics>
          <damping>0.5</damping>
          <friction>0</friction>
          <spring_reference>0</spring_reference>
          <spring_stiffness>0</spring_stiffness>
        </dynamics>
      </axis>
    </joint>
    <link name='hand_index_flex_3_link'>
      <pose relative_to='hand_index_flex_3_joint'>0 0 0 0 0 0</pose>
      <inertial>
        <pose>0.009599999999999999 0.003 0 0 0 0</pose>
        <mass>0.014999999999999999</mass>
        <inertia>
          <ixx>0.001</ixx>
          <ixy>0</ixy>
          <ixz>0</ixz>
          <iyy>0.001</iyy>
          <iyz>0</iyz>
          <izz>0.001</izz>
        </inertia>
      </inertial>
      <collision name='hand_index_flex_3_link_collision'>
        <pose>0 0 0 0 0 0</pose>
        <geometry>
          <mesh>
            <scale>1 1 1</scale>
            <uri>../../../../pal_hey5/pal_hey5_description/meshes/finger_flex_tip_collision.stl</uri>
          </mesh>
        </geometry>
        <surface>
          <contact>
            <ode/>
          </contact>
          <friction>
            <ode/>
          </friction>
        </surface>
      </collision>
      <visual name='hand_index_flex_3_link_visual'>
        <pose>0 0 0 0 0 0</pose>
        <geometry>
          <mesh>
            <scale>1 1 1</scale>
            <uri>../../../../pal_hey5/pal_hey5_description/meshes/finger_flex_tip_collision.stl</uri>
          </mesh>
        </geometry>
        <material>
          <script>
            <name>Gazebo/Black</name>
            <uri>file://media/materials/scripts/gazebo.material</uri>
          </script>
          <diffuse>0.125 0.125 0.125 1</diffuse>
          <ambient>0.125 0.125 0.125 1</ambient>
        </material>
      </visual>
    </link>
    <joint name='hand_little_abd_joint' type='revolute'>
      <pose relative_to='wrist_ft_link'>0.03200000000000003 0.0042 0.1277 -1.570796326794896 -1.047197551196598 -1.110223024625157e-16</pose>
      <parent>wrist_ft_link</parent>
      <child>hand_little_abd_link</child>
      <axis>
        <xyz>0 0 1</xyz>
        <limit>
          <lower>-0.52359877559829882</lower>
          <upper>0.52359877559829882</upper>
          <effort>2</effort>
          <velocity>2</velocity>
        </limit>
        <dynamics>
          <damping>0.5</damping>
          <friction>0</friction>
          <spring_reference>0</spring_reference>
          <spring_stiffness>0</spring_stiffness>
        </dynamics>
      </axis>
    </joint>
    <link name='hand_little_abd_link'>
      <pose relative_to='hand_little_abd_joint'>0 0 0 0 0 0</pose>
      <inertial>
        <pose>-0.0018 0 0.0028 0 0 0</pose>
        <mass>0.017999999999999999</mass>
        <inertia>
          <ixx>0.001</ixx>
          <ixy>0</ixy>
          <ixz>0</ixz>
          <iyy>0.001</iyy>
          <iyz>0</iyz>
          <izz>0.001</izz>
        </inertia>
      </inertial>
      <collision name='hand_little_abd_link_collision'>
        <pose>0 0 0 0 0 0</pose>
        <geometry>
          <mesh>
            <scale>1 1 1</scale>
            <uri>../../../../pal_hey5/pal_hey5_description/meshes/finger_abd_collision.stl</uri>
          </mesh>
        </geometry>
        <surface>
          <contact>
            <ode/>
          </contact>
          <friction>
            <ode/>
          </friction>
        </surface>
      </collision>
      <visual name='hand_little_abd_link_visual'>
        <pose>0 0 0 0 0 0</pose>
        <geometry>
          <mesh>
            <scale>1 1 1</scale>
            <uri>../../../../pal_hey5/pal_hey5_description/meshes/finger_abd_collision.stl</uri>
          </mesh>
        </geometry>
        <material>
          <script>
            <name>Gazebo/Black</name>
            <uri>file://media/materials/scripts/gazebo.material</uri>
          </script>
          <diffuse>0.125 0.125 0.125 1</diffuse>
          <ambient>0.125 0.125 0.125 1</ambient>
        </material>
      </visual>
    </link>
    <joint name='hand_little_virtual_1_joint' type='revolute'>
      <pose relative_to='hand_little_abd_link'>0.008999999999999999 0 0 1.570796326794896 0 0</pose>
      <parent>hand_little_abd_link</parent>
      <child>hand_little_virtual_1_link</child>
      <axis>
        <xyz>0 0 1</xyz>
        <limit>
          <lower>0</lower>
          <upper>0.78539816339744828</upper>
          <effort>2</effort>
          <velocity>2</velocity>
        </limit>
        <dynamics>
          <damping>0.5</damping>
          <friction>0</friction>
          <spring_reference>0</spring_reference>
          <spring_stiffness>0</spring_stiffness>
        </dynamics>
      </axis>
    </joint>
    <link name='hand_little_virtual_1_link'>
      <pose relative_to='hand_little_virtual_1_joint'>0 0 0 0 0 0</pose>
      <inertial>
        <pose>0.0065 0 0 0 0 0</pose>
        <mass>0.01</mass>
        <inertia>
          <ixx>0.001</ixx>
          <ixy>0</ixy>
          <ixz>0</ixz>
          <iyy>0.001</iyy>
          <iyz>0</iyz>
          <izz>0.001</izz>
        </inertia>
      </inertial>
      <collision name='hand_little_virtual_1_link_collision'>
        <pose>0 0 0 0 0 0</pose>
        <geometry>
          <box>
            <size>0.013 0.002 0.012</size>
          </box>
        </geometry>
        <surface>
          <contact>
            <ode/>
          </contact>
          <friction>
            <ode/>
          </friction>
        </surface>
      </collision>
      <visual name='hand_little_virtual_1_link_visual'>
        <pose>0.0065 0 0 0 0 0</pose>
        <geometry>
          <box>
            <size>0.013 0.002 0.012</size>
          </box>
        </geometry>
        <material>
          <script>
            <name>Gazebo/Black</name>
            <uri>file://media/materials/scripts/gazebo.material</uri>
          </script>
          <diffuse>0.125 0.125 0.125 1</diffuse>
          <ambient>0.125 0.125 0.125 1</ambient>
        </material>
      </visual>
    </link>
    <joint name='hand_little_flex_1_joint' type='revolute'>
      <pose relative_to='hand_little_virtual_1_link'>0.013 0 0 0 0 0</pose>
      <parent>hand_little_virtual_1_link</parent>
      <child>hand_little_flex_1_link</child>
      <axis>
        <xyz>0 0 1</xyz>
        <limit>
          <lower>0</lower>
          <upper>0.78539816339744828</upper>
          <effort>2</effort>
          <velocity>2</velocity>
        </limit>
        <dynamics>
          <damping>0.5</damping>
          <friction>0</friction>
          <spring_reference>0</spring_reference>
          <spring_stiffness>0</spring_stiffness>
        </dynamics>
      </axis>
    </joint>
    <link name='hand_little_flex_1_link'>
      <pose relative_to='hand_little_flex_1_joint'>0 0 0 0 0 0</pose>
      <inertial>
        <pose>0.0047 0.0031 0 0 0 0</pose>
        <mass>0.0089999999999999993</mass>
        <inertia>
          <ixx>0.001</ixx>
          <ixy>0</ixy>
          <ixz>0</ixz>
          <iyy>0.001</iyy>
          <iyz>0</iyz>
          <izz>0.001</izz>
        </inertia>
      </inertial>
      <collision name='hand_little_flex_1_link_collision'>
        <pose>0 0 0 0 0 0</pose>
        <geometry>
          <mesh>
            <scale>1 1 1</scale>
            <uri>../../../../pal_hey5/pal_hey5_description/meshes/finger_flex_collision.stl</uri>
          </mesh>
        </geometry>
        <surface>
          <contact>
            <ode/>
          </contact>
          <friction>
            <ode/>
          </friction>
        </surface>
      </collision>
      <visual name='hand_little_flex_1_link_visual'>
        <pose>0 0 0 0 0 0</pose>
        <geometry>
          <mesh>
            <scale>1 1 1</scale>
            <uri>../../../../pal_hey5/pal_hey5_description/meshes/finger_flex_collision.stl</uri>
          </mesh>
        </geometry>
        <material>
          <script>
            <name>Gazebo/Black</name>
            <uri>file://media/materials/scripts/gazebo.material</uri>
          </script>
          <diffuse>0.125 0.125 0.125 1</diffuse>
          <ambient>0.125 0.125 0.125 1</ambient>
        </material>
      </visual>
    </link>
    <joint name='hand_little_virtual_2_joint' type='revolute'>
      <pose relative_to='hand_little_flex_1_link'>0.008999999999999999 0 0 0 0 0</pose>
      <parent>hand_little_flex_1_link</parent>
      <child>hand_little_virtual_2_link</child>
      <axis>
        <xyz>0 0 1</xyz>
        <limit>
          <lower>0</lower>
          <upper>0.78539816339744828</upper>
          <effort>2</effort>
          <velocity>2</velocity>
        </limit>
        <dynamics>
          <damping>0.5</damping>
          <friction>0</friction>
          <spring_reference>0</spring_reference>
          <spring_stiffness>0</spring_stiffness>
        </dynamics>
      </axis>
    </joint>
    <link name='hand_little_virtual_2_link'>
      <pose relative_to='hand_little_virtual_2_joint'>0 0 0 0 0 0</pose>
      <inertial>
        <pose>0.0065 0 0 0 0 0</pose>
        <mass>0.01</mass>
        <inertia>
          <ixx>0.001</ixx>
          <ixy>0</ixy>
          <ixz>0</ixz>
          <iyy>0.001</iyy>
          <iyz>0</iyz>
          <izz>0.001</izz>
        </inertia>
      </inertial>
      <collision name='hand_little_virtual_2_link_collision'>
        <pose>0 0 0 0 0 0</pose>
        <geometry>
          <box>
            <size>0.013 0.002 0.012</size>
          </box>
        </geometry>
        <surface>
          <contact>
            <ode/>
          </contact>
          <friction>
            <ode/>
          </friction>
        </surface>
      </collision>
      <visual name='hand_little_virtual_2_link_visual'>
        <pose>0.0065 0 0 0 0 0</pose>
        <geometry>
          <box>
            <size>0.013 0.002 0.012</size>
          </box>
        </geometry>
        <material>
          <script>
            <name>Gazebo/Black</name>
            <uri>file://media/materials/scripts/gazebo.material</uri>
          </script>
          <diffuse>0.125 0.125 0.125 1</diffuse>
          <ambient>0.125 0.125 0.125 1</ambient>
        </material>
      </visual>
    </link>
    <joint name='hand_little_flex_2_joint' type='revolute'>
      <pose relative_to='hand_little_virtual_2_link'>0.013 0 0 0 0 0</pose>
      <parent>hand_little_virtual_2_link</parent>
      <child>hand_little_flex_2_link</child>
      <axis>
        <xyz>0 0 1</xyz>
        <limit>
          <lower>0</lower>
          <upper>0.78539816339744828</upper>
          <effort>2</effort>
          <velocity>2</velocity>
        </limit>
        <dynamics>
          <damping>0.5</damping>
          <friction>0</friction>
          <spring_reference>0</spring_reference>
          <spring_stiffness>0</spring_stiffness>
        </dynamics>
      </axis>
    </joint>
    <link name='hand_little_flex_2_link'>
      <pose relative_to='hand_little_flex_2_joint'>0 0 0 0 0 0</pose>
      <inertial>
        <pose>0.0047 0.0031 0 0 0 0</pose>
        <mass>0.0089999999999999993</mass>
        <inertia>
          <ixx>0.001</ixx>
          <ixy>0</ixy>
          <ixz>0</ixz>
          <iyy>0.001</iyy>
          <iyz>0</iyz>
          <izz>0.001</izz>
        </inertia>
      </inertial>
      <collision name='hand_little_flex_2_link_collision'>
        <pose>0 0 0 0 0 0</pose>
        <geometry>
          <mesh>
            <scale>1 1 1</scale>
            <uri>../../../../pal_hey5/pal_hey5_description/meshes/finger_flex_collision.stl</uri>
          </mesh>
        </geometry>
        <surface>
          <contact>
            <ode/>
          </contact>
          <friction>
            <ode/>
          </friction>
        </surface>
      </collision>
      <visual name='hand_little_flex_2_link_visual'>
        <pose>0 0 0 0 0 0</pose>
        <geometry>
          <mesh>
            <scale>1 1 1</scale>
            <uri>../../../../pal_hey5/pal_hey5_description/meshes/finger_flex_collision.stl</uri>
          </mesh>
        </geometry>
        <material>
          <script>
            <name>Gazebo/Black</name>
            <uri>file://media/materials/scripts/gazebo.material</uri>
          </script>
          <diffuse>0.125 0.125 0.125 1</diffuse>
          <ambient>0.125 0.125 0.125 1</ambient>
        </material>
      </visual>
    </link>
    <joint name='hand_little_virtual_3_joint' type='revolute'>
      <pose relative_to='hand_little_flex_2_link'>0.008999999999999999 0 0 0 0 0</pose>
      <parent>hand_little_flex_2_link</parent>
      <child>hand_little_virtual_3_link</child>
      <axis>
        <xyz>0 0 1</xyz>
        <limit>
          <lower>0</lower>
          <upper>0.78539816339744828</upper>
          <effort>2</effort>
          <velocity>2</velocity>
        </limit>
        <dynamics>
          <damping>0.5</damping>
          <friction>0</friction>
          <spring_reference>0</spring_reference>
          <spring_stiffness>0</spring_stiffness>
        </dynamics>
      </axis>
    </joint>
    <link name='hand_little_virtual_3_link'>
      <pose relative_to='hand_little_virtual_3_joint'>0 0 0 0 0 0</pose>
      <inertial>
        <pose>0.0065 0 0 0 0 0</pose>
        <mass>0.01</mass>
        <inertia>
          <ixx>0.001</ixx>
          <ixy>0</ixy>
          <ixz>0</ixz>
          <iyy>0.001</iyy>
          <iyz>0</iyz>
          <izz>0.001</izz>
        </inertia>
      </inertial>
      <collision name='hand_little_virtual_3_link_collision'>
        <pose>0 0 0 0 0 0</pose>
        <geometry>
          <box>
            <size>0.013 0.002 0.012</size>
          </box>
        </geometry>
        <surface>
          <contact>
            <ode/>
          </contact>
          <friction>
            <ode/>
          </friction>
        </surface>
      </collision>
      <visual name='hand_little_virtual_3_link_visual'>
        <pose>0.0065 0 0 0 0 0</pose>
        <geometry>
          <box>
            <size>0.013 0.002 0.012</size>
          </box>
        </geometry>
        <material>
          <script>
            <name>Gazebo/Black</name>
            <uri>file://media/materials/scripts/gazebo.material</uri>
          </script>
          <diffuse>0.125 0.125 0.125 1</diffuse>
          <ambient>0.125 0.125 0.125 1</ambient>
        </material>
      </visual>
    </link>
    <joint name='hand_little_flex_3_joint' type='revolute'>
      <pose relative_to='hand_little_virtual_3_link'>0.013 0 0 0 0 0</pose>
      <parent>hand_little_virtual_3_link</parent>
      <child>hand_little_flex_3_link</child>
      <axis>
        <xyz>0 0 1</xyz>
        <limit>
          <lower>0</lower>
          <upper>0.78539816339744828</upper>
          <effort>2</effort>
          <velocity>2</velocity>
        </limit>
        <dynamics>
          <damping>0.5</damping>
          <friction>0</friction>
          <spring_reference>0</spring_reference>
          <spring_stiffness>0</spring_stiffness>
        </dynamics>
      </axis>
    </joint>
    <link name='hand_little_flex_3_link'>
      <pose relative_to='hand_little_flex_3_joint'>0 0 0 0 0 0</pose>
      <inertial>
        <pose>0.009599999999999999 0.003 0 0 0 0</pose>
        <mass>0.014999999999999999</mass>
        <inertia>
          <ixx>0.001</ixx>
          <ixy>0</ixy>
          <ixz>0</ixz>
          <iyy>0.001</iyy>
          <iyz>0</iyz>
          <izz>0.001</izz>
        </inertia>
      </inertial>
      <collision name='hand_little_flex_3_link_collision'>
        <pose>0 0 0 0 0 0</pose>
        <geometry>
          <mesh>
            <scale>1 1 1</scale>
            <uri>../../../../pal_hey5/pal_hey5_description/meshes/finger_flex_tip_collision.stl</uri>
          </mesh>
        </geometry>
        <surface>
          <contact>
            <ode/>
          </contact>
          <friction>
            <ode/>
          </friction>
        </surface>
      </collision>
      <visual name='hand_little_flex_3_link_visual'>
        <pose>0 0 0 0 0 0</pose>
        <geometry>
          <mesh>
            <scale>1 1 1</scale>
            <uri>../../../../pal_hey5/pal_hey5_description/meshes/finger_flex_tip_collision.stl</uri>
          </mesh>
        </geometry>
        <material>
          <script>
            <name>Gazebo/Black</name>
            <uri>file://media/materials/scripts/gazebo.material</uri>
          </script>
          <diffuse>0.125 0.125 0.125 1</diffuse>
          <ambient>0.125 0.125 0.125 1</ambient>
        </material>
      </visual>
    </link>
    <joint name='hand_middle_abd_joint' type='revolute'>
      <pose relative_to='wrist_ft_link'>-0.006999999999999978 0.0042 0.1447 -1.570796326794896 -1.570796326794897 0</pose>
      <parent>wrist_ft_link</parent>
      <child>hand_middle_abd_link</child>
      <axis>
        <xyz>0 0 1</xyz>
        <limit>
          <lower>-0.52359877559829882</lower>
          <upper>0.52359877559829882</upper>
          <effort>2</effort>
          <velocity>2</velocity>
        </limit>
        <dynamics>
          <damping>0.5</damping>
          <friction>0</friction>
          <spring_reference>0</spring_reference>
          <spring_stiffness>0</spring_stiffness>
        </dynamics>
      </axis>
    </joint>
    <link name='hand_middle_abd_link'>
      <pose relative_to='hand_middle_abd_joint'>0 0 0 0 0 0</pose>
      <inertial>
        <pose>-0.0018 0 0.0028 0 0 0</pose>
        <mass>0.017999999999999999</mass>
        <inertia>
          <ixx>0.001</ixx>
          <ixy>0</ixy>
          <ixz>0</ixz>
          <iyy>0.001</iyy>
          <iyz>0</iyz>
          <izz>0.001</izz>
        </inertia>
      </inertial>
      <collision name='hand_middle_abd_link_collision'>
        <pose>0 0 0 0 0 0</pose>
        <geometry>
          <mesh>
            <scale>1 1 1</scale>
            <uri>../../../../pal_hey5/pal_hey5_description/meshes/finger_abd_collision.stl</uri>
          </mesh>
        </geometry>
        <surface>
          <contact>
            <ode/>
          </contact>
          <friction>
            <ode/>
          </friction>
        </surface>
      </collision>
      <visual name='hand_middle_abd_link_visual'>
        <pose>0 0 0 0 0 0</pose>
        <geometry>
          <mesh>
            <scale>1 1 1</scale>
            <uri>../../../../pal_hey5/pal_hey5_description/meshes/finger_abd_collision.stl</uri>
          </mesh>
        </geometry>
        <material>
          <script>
            <name>Gazebo/Black</name>
            <uri>file://media/materials/scripts/gazebo.material</uri>
          </script>
          <diffuse>0.125 0.125 0.125 1</diffuse>
          <ambient>0.125 0.125 0.125 1</ambient>
        </material>
      </visual>
    </link>
    <joint name='hand_middle_virtual_1_joint' type='revolute'>
      <pose relative_to='hand_middle_abd_link'>0.008999999999999999 0 0 1.570796326794896 0 0</pose>
      <parent>hand_middle_abd_link</parent>
      <child>hand_middle_virtual_1_link</child>
      <axis>
        <xyz>0 0 1</xyz>
        <limit>
          <lower>0</lower>
          <upper>0.78539816339744828</upper>
          <effort>2</effort>
          <velocity>2</velocity>
        </limit>
        <dynamics>
          <damping>0.5</damping>
          <friction>0</friction>
          <spring_reference>0</spring_reference>
          <spring_stiffness>0</spring_stiffness>
        </dynamics>
      </axis>
    </joint>
    <link name='hand_middle_virtual_1_link'>
      <pose relative_to='hand_middle_virtual_1_joint'>0 0 0 0 0 0</pose>
      <inertial>
        <pose>0.0065 0 0 0 0 0</pose>
        <mass>0.01</mass>
        <inertia>
          <ixx>0.001</ixx>
          <ixy>0</ixy>
          <ixz>0</ixz>
          <iyy>0.001</iyy>
          <iyz>0</iyz>
          <izz>0.001</izz>
        </inertia>
      </inertial>
      <collision name='hand_middle_virtual_1_link_collision'>
        <pose>0 0 0 0 0 0</pose>
        <geometry>
          <box>
            <size>0.013 0.002 0.012</size>
          </box>
        </geometry>
        <surface>
          <contact>
            <ode/>
          </contact>
          <friction>
            <ode/>
          </friction>
        </surface>
      </collision>
      <visual name='hand_middle_virtual_1_link_visual'>
        <pose>0.0065 0 0 0 0 0</pose>
        <geometry>
          <box>
            <size>0.013 0.002 0.012</size>
          </box>
        </geometry>
        <material>
          <script>
            <name>Gazebo/Black</name>
            <uri>file://media/materials/scripts/gazebo.material</uri>
          </script>
          <diffuse>0.125 0.125 0.125 1</diffuse>
          <ambient>0.125 0.125 0.125 1</ambient>
        </material>
      </visual>
    </link>
    <joint name='hand_middle_flex_1_joint' type='revolute'>
      <pose relative_to='hand_middle_virtual_1_link'>0.013 0 0 0 0 0</pose>
      <parent>hand_middle_virtual_1_link</parent>
      <child>hand_middle_flex_1_link</child>
      <axis>
        <xyz>0 0 1</xyz>
        <limit>
          <lower>0</lower>
          <upper>0.78539816339744828</upper>
          <effort>2</effort>
          <velocity>2</velocity>
        </limit>
        <dynamics>
          <damping>0.5</damping>
          <friction>0</friction>
          <spring_reference>0</spring_reference>
          <spring_stiffness>0</spring_stiffness>
        </dynamics>
      </axis>
    </joint>
    <link name='hand_middle_flex_1_link'>
      <pose relative_to='hand_middle_flex_1_joint'>0 0 0 0 0 0</pose>
      <inertial>
        <pose>0.0047 0.0031 0 0 0 0</pose>
        <mass>0.0089999999999999993</mass>
        <inertia>
          <ixx>0.001</ixx>
          <ixy>0</ixy>
          <ixz>0</ixz>
          <iyy>0.001</iyy>
          <iyz>0</iyz>
          <izz>0.001</izz>
        </inertia>
      </inertial>
      <collision name='hand_middle_flex_1_link_collision'>
        <pose>0 0 0 0 0 0</pose>
        <geometry>
          <mesh>
            <scale>1 1 1</scale>
            <uri>../../../../pal_hey5/pal_hey5_description/meshes/finger_flex_collision.stl</uri>
          </mesh>
        </geometry>
        <surface>
          <contact>
            <ode/>
          </contact>
          <friction>
            <ode/>
          </friction>
        </surface>
      </collision>
      <visual name='hand_middle_flex_1_link_visual'>
        <pose>0 0 0 0 0 0</pose>
        <geometry>
          <mesh>
            <scale>1 1 1</scale>
            <uri>../../../../pal_hey5/pal_hey5_description/meshes/finger_flex_collision.stl</uri>
          </mesh>
        </geometry>
        <material>
          <script>
            <name>Gazebo/Black</name>
            <uri>file://media/materials/scripts/gazebo.material</uri>
          </script>
          <diffuse>0.125 0.125 0.125 1</diffuse>
          <ambient>0.125 0.125 0.125 1</ambient>
        </material>
      </visual>
    </link>
    <joint name='hand_middle_virtual_2_joint' type='revolute'>
      <pose relative_to='hand_middle_flex_1_link'>0.008999999999999999 0 0 0 0 0</pose>
      <parent>hand_middle_flex_1_link</parent>
      <child>hand_middle_virtual_2_link</child>
      <axis>
        <xyz>0 0 1</xyz>
        <limit>
          <lower>0</lower>
          <upper>0.78539816339744828</upper>
          <effort>2</effort>
          <velocity>2</velocity>
        </limit>
        <dynamics>
          <damping>0.5</damping>
          <friction>0</friction>
          <spring_reference>0</spring_reference>
          <spring_stiffness>0</spring_stiffness>
        </dynamics>
      </axis>
    </joint>
    <link name='hand_middle_virtual_2_link'>
      <pose relative_to='hand_middle_virtual_2_joint'>0 0 0 0 0 0</pose>
      <inertial>
        <pose>0.0065 0 0 0 0 0</pose>
        <mass>0.01</mass>
        <inertia>
          <ixx>0.001</ixx>
          <ixy>0</ixy>
          <ixz>0</ixz>
          <iyy>0.001</iyy>
          <iyz>0</iyz>
          <izz>0.001</izz>
        </inertia>
      </inertial>
      <collision name='hand_middle_virtual_2_link_collision'>
        <pose>0 0 0 0 0 0</pose>
        <geometry>
          <box>
            <size>0.013 0.002 0.012</size>
          </box>
        </geometry>
        <surface>
          <contact>
            <ode/>
          </contact>
          <friction>
            <ode/>
          </friction>
        </surface>
      </collision>
      <visual name='hand_middle_virtual_2_link_visual'>
        <pose>0.0065 0 0 0 0 0</pose>
        <geometry>
          <box>
            <size>0.013 0.002 0.012</size>
          </box>
        </geometry>
        <material>
          <script>
            <name>Gazebo/Black</name>
            <uri>file://media/materials/scripts/gazebo.material</uri>
          </script>
          <diffuse>0.125 0.125 0.125 1</diffuse>
          <ambient>0.125 0.125 0.125 1</ambient>
        </material>
      </visual>
    </link>
    <joint name='hand_middle_flex_2_joint' type='revolute'>
      <pose relative_to='hand_middle_virtual_2_link'>0.013 0 0 0 0 0</pose>
      <parent>hand_middle_virtual_2_link</parent>
      <child>hand_middle_flex_2_link</child>
      <axis>
        <xyz>0 0 1</xyz>
        <limit>
          <lower>0</lower>
          <upper>0.78539816339744828</upper>
          <effort>2</effort>
          <velocity>2</velocity>
        </limit>
        <dynamics>
          <damping>0.5</damping>
          <friction>0</friction>
          <spring_reference>0</spring_reference>
          <spring_stiffness>0</spring_stiffness>
        </dynamics>
      </axis>
    </joint>
    <link name='hand_middle_flex_2_link'>
      <pose relative_to='hand_middle_flex_2_joint'>0 0 0 0 0 0</pose>
      <inertial>
        <pose>0.0047 0.0031 0 0 0 0</pose>
        <mass>0.0089999999999999993</mass>
        <inertia>
          <ixx>0.001</ixx>
          <ixy>0</ixy>
          <ixz>0</ixz>
          <iyy>0.001</iyy>
          <iyz>0</iyz>
          <izz>0.001</izz>
        </inertia>
      </inertial>
      <collision name='hand_middle_flex_2_link_collision'>
        <pose>0 0 0 0 0 0</pose>
        <geometry>
          <mesh>
            <scale>1 1 1</scale>
            <uri>../../../../pal_hey5/pal_hey5_description/meshes/finger_flex_collision.stl</uri>
          </mesh>
        </geometry>
        <surface>
          <contact>
            <ode/>
          </contact>
          <friction>
            <ode/>
          </friction>
        </surface>
      </collision>
      <visual name='hand_middle_flex_2_link_visual'>
        <pose>0 0 0 0 0 0</pose>
        <geometry>
          <mesh>
            <scale>1 1 1</scale>
            <uri>../../../../pal_hey5/pal_hey5_description/meshes/finger_flex_collision.stl</uri>
          </mesh>
        </geometry>
        <material>
          <script>
            <name>Gazebo/Black</name>
            <uri>file://media/materials/scripts/gazebo.material</uri>
          </script>
          <diffuse>0.125 0.125 0.125 1</diffuse>
          <ambient>0.125 0.125 0.125 1</ambient>
        </material>
      </visual>
    </link>
    <joint name='hand_middle_virtual_3_joint' type='revolute'>
      <pose relative_to='hand_middle_flex_2_link'>0.008999999999999999 0 0 0 0 0</pose>
      <parent>hand_middle_flex_2_link</parent>
      <child>hand_middle_virtual_3_link</child>
      <axis>
        <xyz>0 0 1</xyz>
        <limit>
          <lower>0</lower>
          <upper>0.78539816339744828</upper>
          <effort>2</effort>
          <velocity>2</velocity>
        </limit>
        <dynamics>
          <damping>0.5</damping>
          <friction>0</friction>
          <spring_reference>0</spring_reference>
          <spring_stiffness>0</spring_stiffness>
        </dynamics>
      </axis>
    </joint>
    <link name='hand_middle_virtual_3_link'>
      <pose relative_to='hand_middle_virtual_3_joint'>0 0 0 0 0 0</pose>
      <inertial>
        <pose>0.0065 0 0 0 0 0</pose>
        <mass>0.01</mass>
        <inertia>
          <ixx>0.001</ixx>
          <ixy>0</ixy>
          <ixz>0</ixz>
          <iyy>0.001</iyy>
          <iyz>0</iyz>
          <izz>0.001</izz>
        </inertia>
      </inertial>
      <collision name='hand_middle_virtual_3_link_collision'>
        <pose>0 0 0 0 0 0</pose>
        <geometry>
          <box>
            <size>0.013 0.002 0.012</size>
          </box>
        </geometry>
        <surface>
          <contact>
            <ode/>
          </contact>
          <friction>
            <ode/>
          </friction>
        </surface>
      </collision>
      <visual name='hand_middle_virtual_3_link_visual'>
        <pose>0.0065 0 0 0 0 0</pose>
        <geometry>
          <box>
            <size>0.013 0.002 0.012</size>
          </box>
        </geometry>
        <material>
          <script>
            <name>Gazebo/Black</name>
            <uri>file://media/materials/scripts/gazebo.material</uri>
          </script>
          <diffuse>0.125 0.125 0.125 1</diffuse>
          <ambient>0.125 0.125 0.125 1</ambient>
        </material>
      </visual>
    </link>
    <joint name='hand_middle_flex_3_joint' type='revolute'>
      <pose relative_to='hand_middle_virtual_3_link'>0.013 0 0 0 0 0</pose>
      <parent>hand_middle_virtual_3_link</parent>
      <child>hand_middle_flex_3_link</child>
      <axis>
        <xyz>0 0 1</xyz>
        <limit>
          <lower>0</lower>
          <upper>0.78539816339744828</upper>
          <effort>2</effort>
          <velocity>2</velocity>
        </limit>
        <dynamics>
          <damping>0.5</damping>
          <friction>0</friction>
          <spring_reference>0</spring_reference>
          <spring_stiffness>0</spring_stiffness>
        </dynamics>
      </axis>
    </joint>
    <link name='hand_middle_flex_3_link'>
      <pose relative_to='hand_middle_flex_3_joint'>0 0 0 0 0 0</pose>
      <inertial>
        <pose>0.009599999999999999 0.003 0 0 0 0</pose>
        <mass>0.014999999999999999</mass>
        <inertia>
          <ixx>0.001</ixx>
          <ixy>0</ixy>
          <ixz>0</ixz>
          <iyy>0.001</iyy>
          <iyz>0</iyz>
          <izz>0.001</izz>
        </inertia>
      </inertial>
      <collision name='hand_middle_flex_3_link_collision'>
        <pose>0 0 0 0 0 0</pose>
        <geometry>
          <mesh>
            <scale>1 1 1</scale>
            <uri>../../../../pal_hey5/pal_hey5_description/meshes/finger_flex_tip_collision.stl</uri>
          </mesh>
        </geometry>
        <surface>
          <contact>
            <ode/>
          </contact>
          <friction>
            <ode/>
          </friction>
        </surface>
      </collision>
      <visual name='hand_middle_flex_3_link_visual'>
        <pose>0 0 0 0 0 0</pose>
        <geometry>
          <mesh>
            <scale>1 1 1</scale>
            <uri>../../../../pal_hey5/pal_hey5_description/meshes/finger_flex_tip_collision.stl</uri>
          </mesh>
        </geometry>
        <material>
          <script>
            <name>Gazebo/Black</name>
            <uri>file://media/materials/scripts/gazebo.material</uri>
          </script>
          <diffuse>0.125 0.125 0.125 1</diffuse>
          <ambient>0.125 0.125 0.125 1</ambient>
        </material>
      </visual>
    </link>
    <joint name='hand_ring_abd_joint' type='revolute'>
      <pose relative_to='wrist_ft_link'>0.01250000000000004 0.0042 0.1377 -1.570796326794897 -1.308996938995748 0</pose>
      <parent>wrist_ft_link</parent>
      <child>hand_ring_abd_link</child>
      <axis>
        <xyz>0 0 1</xyz>
        <limit>
          <lower>-0.52359877559829882</lower>
          <upper>0.52359877559829882</upper>
          <effort>2</effort>
          <velocity>2</velocity>
        </limit>
        <dynamics>
          <damping>0.5</damping>
          <friction>0</friction>
          <spring_reference>0</spring_reference>
          <spring_stiffness>0</spring_stiffness>
        </dynamics>
      </axis>
    </joint>
    <link name='hand_ring_abd_link'>
      <pose relative_to='hand_ring_abd_joint'>0 0 0 0 0 0</pose>
      <inertial>
        <pose>-0.0018 0 0.0028 0 0 0</pose>
        <mass>0.017999999999999999</mass>
        <inertia>
          <ixx>0.001</ixx>
          <ixy>0</ixy>
          <ixz>0</ixz>
          <iyy>0.001</iyy>
          <iyz>0</iyz>
          <izz>0.001</izz>
        </inertia>
      </inertial>
      <collision name='hand_ring_abd_link_collision'>
        <pose>0 0 0 0 0 0</pose>
        <geometry>
          <mesh>
            <scale>1 1 1</scale>
            <uri>../../../../pal_hey5/pal_hey5_description/meshes/finger_abd_collision.stl</uri>
          </mesh>
        </geometry>
        <surface>
          <contact>
            <ode/>
          </contact>
          <friction>
            <ode/>
          </friction>
        </surface>
      </collision>
      <visual name='hand_ring_abd_link_visual'>
        <pose>0 0 0 0 0 0</pose>
        <geometry>
          <mesh>
            <scale>1 1 1</scale>
            <uri>../../../../pal_hey5/pal_hey5_description/meshes/finger_abd_collision.stl</uri>
          </mesh>
        </geometry>
        <material>
          <script>
            <name>Gazebo/Black</name>
            <uri>file://media/materials/scripts/gazebo.material</uri>
          </script>
          <diffuse>0.125 0.125 0.125 1</diffuse>
          <ambient>0.125 0.125 0.125 1</ambient>
        </material>
      </visual>
    </link>
    <joint name='hand_ring_virtual_1_joint' type='revolute'>
      <pose relative_to='hand_ring_abd_link'>0.008999999999999999 0 0 1.570796326794896 0 0</pose>
      <parent>hand_ring_abd_link</parent>
      <child>hand_ring_virtual_1_link</child>
      <axis>
        <xyz>0 0 1</xyz>
        <limit>
          <lower>0</lower>
          <upper>0.78539816339744828</upper>
          <effort>2</effort>
          <velocity>2</velocity>
        </limit>
        <dynamics>
          <damping>0.5</damping>
          <friction>0</friction>
          <spring_reference>0</spring_reference>
          <spring_stiffness>0</spring_stiffness>
        </dynamics>
      </axis>
    </joint>
    <link name='hand_ring_virtual_1_link'>
      <pose relative_to='hand_ring_virtual_1_joint'>0 0 0 0 0 0</pose>
      <inertial>
        <pose>0.0065 0 0 0 0 0</pose>
        <mass>0.01</mass>
        <inertia>
          <ixx>0.001</ixx>
          <ixy>0</ixy>
          <ixz>0</ixz>
          <iyy>0.001</iyy>
          <iyz>0</iyz>
          <izz>0.001</izz>
        </inertia>
      </inertial>
      <collision name='hand_ring_virtual_1_link_collision'>
        <pose>0 0 0 0 0 0</pose>
        <geometry>
          <box>
            <size>0.013 0.002 0.012</size>
          </box>
        </geometry>
        <surface>
          <contact>
            <ode/>
          </contact>
          <friction>
            <ode/>
          </friction>
        </surface>
      </collision>
      <visual name='hand_ring_virtual_1_link_visual'>
        <pose>0.0065 0 0 0 0 0</pose>
        <geometry>
          <box>
            <size>0.013 0.002 0.012</size>
          </box>
        </geometry>
        <material>
          <script>
            <name>Gazebo/Black</name>
            <uri>file://media/materials/scripts/gazebo.material</uri>
          </script>
          <diffuse>0.125 0.125 0.125 1</diffuse>
          <ambient>0.125 0.125 0.125 1</ambient>
        </material>
      </visual>
    </link>
    <joint name='hand_ring_flex_1_joint' type='revolute'>
      <pose relative_to='hand_ring_virtual_1_link'>0.013 0 0 0 0 0</pose>
      <parent>hand_ring_virtual_1_link</parent>
      <child>hand_ring_flex_1_link</child>
      <axis>
        <xyz>0 0 1</xyz>
        <limit>
          <lower>0</lower>
          <upper>0.78539816339744828</upper>
          <effort>2</effort>
          <velocity>2</velocity>
        </limit>
        <dynamics>
          <damping>0.5</damping>
          <friction>0</friction>
          <spring_reference>0</spring_reference>
          <spring_stiffness>0</spring_stiffness>
        </dynamics>
      </axis>
    </joint>
    <link name='hand_ring_flex_1_link'>
      <pose relative_to='hand_ring_flex_1_joint'>0 0 0 0 0 0</pose>
      <inertial>
        <pose>0.0047 0.0031 0 0 0 0</pose>
        <mass>0.0089999999999999993</mass>
        <inertia>
          <ixx>0.001</ixx>
          <ixy>0</ixy>
          <ixz>0</ixz>
          <iyy>0.001</iyy>
          <iyz>0</iyz>
          <izz>0.001</izz>
        </inertia>
      </inertial>
      <collision name='hand_ring_flex_1_link_collision'>
        <pose>0 0 0 0 0 0</pose>
        <geometry>
          <mesh>
            <scale>1 1 1</scale>
            <uri>../../../../pal_hey5/pal_hey5_description/meshes/finger_flex_collision.stl</uri>
          </mesh>
        </geometry>
        <surface>
          <contact>
            <ode/>
          </contact>
          <friction>
            <ode/>
          </friction>
        </surface>
      </collision>
      <visual name='hand_ring_flex_1_link_visual'>
        <pose>0 0 0 0 0 0</pose>
        <geometry>
          <mesh>
            <scale>1 1 1</scale>
            <uri>../../../../pal_hey5/pal_hey5_description/meshes/finger_flex_collision.stl</uri>
          </mesh>
        </geometry>
        <material>
          <script>
            <name>Gazebo/Black</name>
            <uri>file://media/materials/scripts/gazebo.material</uri>
          </script>
          <diffuse>0.125 0.125 0.125 1</diffuse>
          <ambient>0.125 0.125 0.125 1</ambient>
        </material>
      </visual>
    </link>
    <joint name='hand_ring_virtual_2_joint' type='revolute'>
      <pose relative_to='hand_ring_flex_1_link'>0.008999999999999999 0 0 0 0 0</pose>
      <parent>hand_ring_flex_1_link</parent>
      <child>hand_ring_virtual_2_link</child>
      <axis>
        <xyz>0 0 1</xyz>
        <limit>
          <lower>0</lower>
          <upper>0.78539816339744828</upper>
          <effort>2</effort>
          <velocity>2</velocity>
        </limit>
        <dynamics>
          <damping>0.5</damping>
          <friction>0</friction>
          <spring_reference>0</spring_reference>
          <spring_stiffness>0</spring_stiffness>
        </dynamics>
      </axis>
    </joint>
    <link name='hand_ring_virtual_2_link'>
      <pose relative_to='hand_ring_virtual_2_joint'>0 0 0 0 0 0</pose>
      <inertial>
        <pose>0.0065 0 0 0 0 0</pose>
        <mass>0.01</mass>
        <inertia>
          <ixx>0.001</ixx>
          <ixy>0</ixy>
          <ixz>0</ixz>
          <iyy>0.001</iyy>
          <iyz>0</iyz>
          <izz>0.001</izz>
        </inertia>
      </inertial>
      <collision name='hand_ring_virtual_2_link_collision'>
        <pose>0 0 0 0 0 0</pose>
        <geometry>
          <box>
            <size>0.013 0.002 0.012</size>
          </box>
        </geometry>
        <surface>
          <contact>
            <ode/>
          </contact>
          <friction>
            <ode/>
          </friction>
        </surface>
      </collision>
      <visual name='hand_ring_virtual_2_link_visual'>
        <pose>0.0065 0 0 0 0 0</pose>
        <geometry>
          <box>
            <size>0.013 0.002 0.012</size>
          </box>
        </geometry>
        <material>
          <script>
            <name>Gazebo/Black</name>
            <uri>file://media/materials/scripts/gazebo.material</uri>
          </script>
          <diffuse>0.125 0.125 0.125 1</diffuse>
          <ambient>0.125 0.125 0.125 1</ambient>
        </material>
      </visual>
    </link>
    <joint name='hand_ring_flex_2_joint' type='revolute'>
      <pose relative_to='hand_ring_virtual_2_link'>0.013 0 0 0 0 0</pose>
      <parent>hand_ring_virtual_2_link</parent>
      <child>hand_ring_flex_2_link</child>
      <axis>
        <xyz>0 0 1</xyz>
        <limit>
          <lower>0</lower>
          <upper>0.78539816339744828</upper>
          <effort>2</effort>
          <velocity>2</velocity>
        </limit>
        <dynamics>
          <damping>0.5</damping>
          <friction>0</friction>
          <spring_reference>0</spring_reference>
          <spring_stiffness>0</spring_stiffness>
        </dynamics>
      </axis>
    </joint>
    <link name='hand_ring_flex_2_link'>
      <pose relative_to='hand_ring_flex_2_joint'>0 0 0 0 0 0</pose>
      <inertial>
        <pose>0.0047 0.0031 0 0 0 0</pose>
        <mass>0.0089999999999999993</mass>
        <inertia>
          <ixx>0.001</ixx>
          <ixy>0</ixy>
          <ixz>0</ixz>
          <iyy>0.001</iyy>
          <iyz>0</iyz>
          <izz>0.001</izz>
        </inertia>
      </inertial>
      <collision name='hand_ring_flex_2_link_collision'>
        <pose>0 0 0 0 0 0</pose>
        <geometry>
          <mesh>
            <scale>1 1 1</scale>
            <uri>../../../../pal_hey5/pal_hey5_description/meshes/finger_flex_collision.stl</uri>
          </mesh>
        </geometry>
        <surface>
          <contact>
            <ode/>
          </contact>
          <friction>
            <ode/>
          </friction>
        </surface>
      </collision>
      <visual name='hand_ring_flex_2_link_visual'>
        <pose>0 0 0 0 0 0</pose>
        <geometry>
          <mesh>
            <scale>1 1 1</scale>
            <uri>../../../../pal_hey5/pal_hey5_description/meshes/finger_flex_collision.stl</uri>
          </mesh>
        </geometry>
        <material>
          <script>
            <name>Gazebo/Black</name>
            <uri>file://media/materials/scripts/gazebo.material</uri>
          </script>
          <diffuse>0.125 0.125 0.125 1</diffuse>
          <ambient>0.125 0.125 0.125 1</ambient>
        </material>
      </visual>
    </link>
    <joint name='hand_ring_virtual_3_joint' type='revolute'>
      <pose relative_to='hand_ring_flex_2_link'>0.008999999999999999 0 0 0 0 0</pose>
      <parent>hand_ring_flex_2_link</parent>
      <child>hand_ring_virtual_3_link</child>
      <axis>
        <xyz>0 0 1</xyz>
        <limit>
          <lower>0</lower>
          <upper>0.78539816339744828</upper>
          <effort>2</effort>
          <velocity>2</velocity>
        </limit>
        <dynamics>
          <damping>0.5</damping>
          <friction>0</friction>
          <spring_reference>0</spring_reference>
          <spring_stiffness>0</spring_stiffness>
        </dynamics>
      </axis>
    </joint>
    <link name='hand_ring_virtual_3_link'>
      <pose relative_to='hand_ring_virtual_3_joint'>0 0 0 0 0 0</pose>
      <inertial>
        <pose>0.0065 0 0 0 0 0</pose>
        <mass>0.01</mass>
        <inertia>
          <ixx>0.001</ixx>
          <ixy>0</ixy>
          <ixz>0</ixz>
          <iyy>0.001</iyy>
          <iyz>0</iyz>
          <izz>0.001</izz>
        </inertia>
      </inertial>
      <collision name='hand_ring_virtual_3_link_collision'>
        <pose>0 0 0 0 0 0</pose>
        <geometry>
          <box>
            <size>0.013 0.002 0.012</size>
          </box>
        </geometry>
        <surface>
          <contact>
            <ode/>
          </contact>
          <friction>
            <ode/>
          </friction>
        </surface>
      </collision>
      <visual name='hand_ring_virtual_3_link_visual'>
        <pose>0.0065 0 0 0 0 0</pose>
        <geometry>
          <box>
            <size>0.013 0.002 0.012</size>
          </box>
        </geometry>
        <material>
          <script>
            <name>Gazebo/Black</name>
            <uri>file://media/materials/scripts/gazebo.material</uri>
          </script>
          <diffuse>0.125 0.125 0.125 1</diffuse>
          <ambient>0.125 0.125 0.125 1</ambient>
        </material>
      </visual>
    </link>
    <joint name='hand_ring_flex_3_joint' type='revolute'>
      <pose relative_to='hand_ring_virtual_3_link'>0.013 0 0 0 0 0</pose>
      <parent>hand_ring_virtual_3_link</parent>
      <child>hand_ring_flex_3_link</child>
      <axis>
        <xyz>0 0 1</xyz>
        <limit>
          <lower>0</lower>
          <upper>0.78539816339744828</upper>
          <effort>2</effort>
          <velocity>2</velocity>
        </limit>
        <dynamics>
          <damping>0.5</damping>
          <friction>0</friction>
          <spring_reference>0</spring_reference>
          <spring_stiffness>0</spring_stiffness>
        </dynamics>
      </axis>
    </joint>
    <link name='hand_ring_flex_3_link'>
      <pose relative_to='hand_ring_flex_3_joint'>0 0 0 0 0 0</pose>
      <inertial>
        <pose>0.009599999999999999 0.003 0 0 0 0</pose>
        <mass>0.014999999999999999</mass>
        <inertia>
          <ixx>0.001</ixx>
          <ixy>0</ixy>
          <ixz>0</ixz>
          <iyy>0.001</iyy>
          <iyz>0</iyz>
          <izz>0.001</izz>
        </inertia>
      </inertial>
      <collision name='hand_ring_flex_3_link_collision'>
        <pose>0 0 0 0 0 0</pose>
        <geometry>
          <mesh>
            <scale>1 1 1</scale>
            <uri>../../../../pal_hey5/pal_hey5_description/meshes/finger_flex_tip_collision.stl</uri>
          </mesh>
        </geometry>
        <surface>
          <contact>
            <ode/>
          </contact>
          <friction>
            <ode/>
          </friction>
        </surface>
      </collision>
      <visual name='hand_ring_flex_3_link_visual'>
        <pose>0 0 0 0 0 0</pose>
        <geometry>
          <mesh>
            <scale>1 1 1</scale>
            <uri>../../../../pal_hey5/pal_hey5_description/meshes/finger_flex_tip_collision.stl</uri>
          </mesh>
        </geometry>
        <material>
          <script>
            <name>Gazebo/Black</name>
            <uri>file://media/materials/scripts/gazebo.material</uri>
          </script>
          <diffuse>0.125 0.125 0.125 1</diffuse>
          <ambient>0.125 0.125 0.125 1</ambient>
        </material>
      </visual>
    </link>
    <joint name='hand_thumb_abd_joint' type='revolute'>
      <pose relative_to='wrist_ft_link'>-0.03799999999999997 0.0134 0.1013 3.141592653589793 -0.4363323129985826 3.141592653589793</pose>
      <parent>wrist_ft_link</parent>
      <child>hand_thumb_abd_link</child>
      <axis>
        <xyz>0 0 1</xyz>
        <limit>
          <lower>0</lower>
          <upper>1.570796326794897</upper>
          <effort>2</effort>
          <velocity>2</velocity>
        </limit>
        <dynamics>
          <damping>0.5</damping>
          <friction>0</friction>
          <spring_reference>0</spring_reference>
          <spring_stiffness>0</spring_stiffness>
        </dynamics>
      </axis>
    </joint>
    <link name='hand_thumb_abd_link'>
      <pose relative_to='hand_thumb_abd_joint'>0 0 0 0 0 0</pose>
      <inertial>
        <pose>-0.0132 0.0037 -0.0017 0 0 0</pose>
        <mass>0.014</mass>
        <inertia>
          <ixx>0.001</ixx>
          <ixy>0</ixy>
          <ixz>0</ixz>
          <iyy>0.001</iyy>
          <iyz>0</iyz>
          <izz>0.001</izz>
        </inertia>
      </inertial>
      <collision name='hand_thumb_abd_link_collision'>
        <pose>0 0 0 0 0 0</pose>
        <geometry>
          <mesh>
            <scale>1 1 1</scale>
            <uri>../../../../pal_hey5/pal_hey5_description/meshes/thumb_abd_collision.stl</uri>
          </mesh>
        </geometry>
        <surface>
          <contact>
            <ode/>
          </contact>
          <friction>
            <ode/>
          </friction>
        </surface>
      </collision>
      <visual name='hand_thumb_abd_link_visual'>
        <pose>0 0 0 0 0 0</pose>
        <geometry>
          <mesh>
            <scale>1 1 1</scale>
            <uri>../../../../pal_hey5/pal_hey5_description/meshes/thumb_abd_collision.stl</uri>
          </mesh>
        </geometry>
        <material>
          <script>
            <name>Gazebo/Black</name>
            <uri>file://media/materials/scripts/gazebo.material</uri>
          </script>
          <diffuse>0.125 0.125 0.125 1</diffuse>
          <ambient>0.125 0.125 0.125 1</ambient>
        </material>
      </visual>
    </link>
    <joint name='hand_thumb_virtual_1_joint' type='revolute'>
      <pose relative_to='hand_thumb_abd_link'>0.0225 0.003 0 -1.144237857607483 0 0</pose>
      <parent>hand_thumb_abd_link</parent>
      <child>hand_thumb_virtual_1_link</child>
      <axis>
        <xyz>0 0 1</xyz>
        <limit>
          <lower>0</lower>
          <upper>0.78539816339744828</upper>
          <effort>2</effort>
          <velocity>2</velocity>
        </limit>
        <dynamics>
          <damping>0.5</damping>
          <friction>0</friction>
          <spring_reference>0</spring_reference>
          <spring_stiffness>0</spring_stiffness>
        </dynamics>
      </axis>
    </joint>
    <link name='hand_thumb_virtual_1_link'>
      <pose relative_to='hand_thumb_virtual_1_joint'>0 0 0 0 0 0</pose>
      <inertial>
        <pose>0.0065 0 0 0 0 0</pose>
        <mass>0.01</mass>
        <inertia>
          <ixx>0.001</ixx>
          <ixy>0</ixy>
          <ixz>0</ixz>
          <iyy>0.001</iyy>
          <iyz>0</iyz>
          <izz>0.001</izz>
        </inertia>
      </inertial>
      <collision name='hand_thumb_virtual_1_link_collision'>
        <pose>0 0 0 0 0 0</pose>
        <geometry>
          <box>
            <size>0.013 0.002 0.012</size>
          </box>
        </geometry>
        <surface>
          <contact>
            <ode/>
          </contact>
          <friction>
            <ode/>
          </friction>
        </surface>
      </collision>
      <visual name='hand_thumb_virtual_1_link_visual'>
        <pose>0.0065 0 0 0 0 0</pose>
        <geometry>
          <box>
            <size>0.013 0.002 0.012</size>
          </box>
        </geometry>
        <material>
          <script>
            <name>Gazebo/Black</name>
            <uri>file://media/materials/scripts/gazebo.material</uri>
          </script>
          <diffuse>0.125 0.125 0.125 1</diffuse>
          <ambient>0.125 0.125 0.125 1</ambient>
        </material>
      </visual>
    </link>
    <joint name='hand_thumb_flex_1_joint' type='revolute'>
      <pose relative_to='hand_thumb_virtual_1_link'>0.013 0 0 0 0 0</pose>
      <parent>hand_thumb_virtual_1_link</parent>
      <child>hand_thumb_flex_1_link</child>
      <axis>
        <xyz>0 0 1</xyz>
        <limit>
          <lower>0</lower>
          <upper>0.78539816339744828</upper>
          <effort>2</effort>
          <velocity>2</velocity>
        </limit>
        <dynamics>
          <damping>0.5</damping>
          <friction>0</friction>
          <spring_reference>0</spring_reference>
          <spring_stiffness>0</spring_stiffness>
        </dynamics>
      </axis>
    </joint>
    <link name='hand_thumb_flex_1_link'>
      <pose relative_to='hand_thumb_flex_1_joint'>0 0 0 0 0 0</pose>
      <inertial>
        <pose>0.0047 0.0031 0 0 0 0</pose>
        <mass>0.0089999999999999993</mass>
        <inertia>
          <ixx>0.001</ixx>
          <ixy>0</ixy>
          <ixz>0</ixz>
          <iyy>0.001</iyy>
          <iyz>0</iyz>
          <izz>0.001</izz>
        </inertia>
      </inertial>
      <collision name='hand_thumb_flex_1_link_collision'>
        <pose>0 0 0 0 0 0</pose>
        <geometry>
          <mesh>
            <scale>1 1 1</scale>
            <uri>../../../../pal_hey5/pal_hey5_description/meshes/finger_flex_collision.stl</uri>
          </mesh>
        </geometry>
        <surface>
          <contact>
            <ode/>
          </contact>
          <friction>
            <ode/>
          </friction>
        </surface>
      </collision>
      <visual name='hand_thumb_flex_1_link_visual'>
        <pose>0 0 0 0 0 0</pose>
        <geometry>
          <mesh>
            <scale>1 1 1</scale>
            <uri>../../../../pal_hey5/pal_hey5_description/meshes/finger_flex_collision.stl</uri>
          </mesh>
        </geometry>
        <material>
          <script>
            <name>Gazebo/Black</name>
            <uri>file://media/materials/scripts/gazebo.material</uri>
          </script>
          <diffuse>0.125 0.125 0.125 1</diffuse>
          <ambient>0.125 0.125 0.125 1</ambient>
        </material>
      </visual>
    </link>
    <joint name='hand_thumb_virtual_2_joint' type='revolute'>
      <pose relative_to='hand_thumb_flex_1_link'>0.008999999999999999 0 0 0 0 0</pose>
      <parent>hand_thumb_flex_1_link</parent>
      <child>hand_thumb_virtual_2_link</child>
      <axis>
        <xyz>0 0 1</xyz>
        <limit>
          <lower>0</lower>
          <upper>0.78539816339744828</upper>
          <effort>2</effort>
          <velocity>2</velocity>
        </limit>
        <dynamics>
          <damping>0.5</damping>
          <friction>0</friction>
          <spring_reference>0</spring_reference>
          <spring_stiffness>0</spring_stiffness>
        </dynamics>
      </axis>
    </joint>
    <link name='hand_thumb_virtual_2_link'>
      <pose relative_to='hand_thumb_virtual_2_joint'>0 0 0 0 0 0</pose>
      <inertial>
        <pose>0.0065 0 0 0 0 0</pose>
        <mass>0.01</mass>
        <inertia>
          <ixx>0.001</ixx>
          <ixy>0</ixy>
          <ixz>0</ixz>
          <iyy>0.001</iyy>
          <iyz>0</iyz>
          <izz>0.001</izz>
        </inertia>
      </inertial>
      <collision name='hand_thumb_virtual_2_link_collision'>
        <pose>0 0 0 0 0 0</pose>
        <geometry>
          <box>
            <size>0.013 0.002 0.012</size>
          </box>
        </geometry>
        <surface>
          <contact>
            <ode/>
          </contact>
          <friction>
            <ode/>
          </friction>
        </surface>
      </collision>
      <visual name='hand_thumb_virtual_2_link_visual'>
        <pose>0.0065 0 0 0 0 0</pose>
        <geometry>
          <box>
            <size>0.013 0.002 0.012</size>
          </box>
        </geometry>
        <material>
          <script>
            <name>Gazebo/Black</name>
            <uri>file://media/materials/scripts/gazebo.material</uri>
          </script>
          <diffuse>0.125 0.125 0.125 1</diffuse>
          <ambient>0.125 0.125 0.125 1</ambient>
        </material>
      </visual>
    </link>
    <joint name='hand_thumb_flex_2_joint' type='revolute'>
      <pose relative_to='hand_thumb_virtual_2_link'>0.013 0 0 0 0 0</pose>
      <parent>hand_thumb_virtual_2_link</parent>
      <child>hand_thumb_flex_2_link</child>
      <axis>
        <xyz>0 0 1</xyz>
        <limit>
          <lower>0</lower>
          <upper>0.78539816339744828</upper>
          <effort>2</effort>
          <velocity>2</velocity>
        </limit>
        <dynamics>
          <damping>0.5</damping>
          <friction>0</friction>
          <spring_reference>0</spring_reference>
          <spring_stiffness>0</spring_stiffness>
        </dynamics>
      </axis>
    </joint>
    <link name='hand_thumb_flex_2_link'>
      <pose relative_to='hand_thumb_flex_2_joint'>0 0 0 0 0 0</pose>
      <inertial>
        <pose>0.009599999999999999 0.003 0 0 0 0</pose>
        <mass>0.014999999999999999</mass>
        <inertia>
          <ixx>0.001</ixx>
          <ixy>0</ixy>
          <ixz>0</ixz>
          <iyy>0.001</iyy>
          <iyz>0</iyz>
          <izz>0.001</izz>
        </inertia>
      </inertial>
      <collision name='hand_thumb_flex_2_link_collision'>
        <pose>0 0 0 0 0 0</pose>
        <geometry>
          <mesh>
            <scale>1 1 1</scale>
            <uri>../../../../pal_hey5/pal_hey5_description/meshes/finger_flex_tip_collision.stl</uri>
          </mesh>
        </geometry>
        <surface>
          <contact>
            <ode/>
          </contact>
          <friction>
            <ode/>
          </friction>
        </surface>
      </collision>
      <visual name='hand_thumb_flex_2_link_visual'>
        <pose>0 0 0 0 0 0</pose>
        <geometry>
          <mesh>
            <scale>1 1 1</scale>
            <uri>../../../../pal_hey5/pal_hey5_description/meshes/finger_flex_tip_collision.stl</uri>
          </mesh>
        </geometry>
        <material>
          <script>
            <name>Gazebo/Black</name>
            <uri>file://media/materials/scripts/gazebo.material</uri>
          </script>
          <diffuse>0.125 0.125 0.125 1</diffuse>
          <ambient>0.125 0.125 0.125 1</ambient>
        </material>
      </visual>
    </link>
    <joint name='head_1_joint' type='revolute'>
      <pose relative_to='torso_lift_link'>0.182 0 0 0 0 0</pose>
      <parent>torso_lift_link</parent>
      <child>head_1_link</child>
      <axis>
        <xyz>0 0 1</xyz>
        <limit>
          <lower>-1.308996938995747</lower>
          <upper>1.308996938995747</upper>
          <effort>5.1970000000000001</effort>
          <velocity>3</velocity>
        </limit>
        <dynamics>
          <damping>0.5</damping>
          <friction>1</friction>
          <spring_reference>0</spring_reference>
          <spring_stiffness>0</spring_stiffness>
        </dynamics>
      </axis>
      <physics>
        <ode>
          <implicit_spring_damper>true</implicit_spring_damper>
          <cfm_damping>true</cfm_damping>
          <limit>
            <cfm>0</cfm>
            <erp>0.20000000000000001</erp>
          </limit>
        </ode>
      </physics>
    </joint>
    <link name='head_1_link'>
      <pose relative_to='head_1_joint'>0 0 0 0 0 0</pose>
      <inertial>
        <pose>-0.00508 0.00237 0.07228999999999999 0 0 0</pose>
        <mass>0.62219999999999998</mass>
        <inertia>
          <ixx>0.0011919999999999999</ixx>
          <ixy>-6.9999999999999999e-06</ixy>
          <ixz>9.6000000000000002e-05</ixz>
          <iyy>0.001402</iyy>
          <iyz>3.9999999999999998e-06</iyz>
          <izz>0.00088900000000000003</izz>
        </inertia>
      </inertial>
      <collision name='head_1_link_collision'>
        <pose>0 0 0 0 0 0</pose>
        <geometry>
          <mesh>
            <scale>1 1 1</scale>
            <uri>meshes/head/head_1_collision.dae</uri>
          </mesh>
        </geometry>
        <surface>
          <contact>
            <ode/>
          </contact>
          <friction>
            <ode>
              <mu>0.90000000000000002</mu>
              <mu2>0.90000000000000002</mu2>
            </ode>
          </friction>
        </surface>
      </collision>
      <visual name='head_1_link_visual'>
        <pose>0 0 0 0 0 0</pose>
        <geometry>
          <mesh>
            <scale>1 1 1</scale>
            <uri>meshes/head/head_1.stl</uri>
          </mesh>
        </geometry>
        <material>
          <diffuse>1 1 1 1</diffuse>
          <ambient>1 1 1 1</ambient>
        </material>
      </visual>
    </link>
    <joint name='head_2_joint' type='revolute'>
      <pose relative_to='head_1_link'>0.005 0 0.098 1.570796326794896 0 0</pose>
      <parent>head_1_link</parent>
      <child>head_2_link</child>
      <axis>
        <xyz>0 0 1</xyz>
        <limit>
          <lower>-1.0471975511965981</lower>
          <upper>0.78539816339744828</upper>
          <effort>2.77</effort>
          <velocity>3</velocity>
        </limit>
        <dynamics>
          <damping>0.5</damping>
          <friction>1</friction>
          <spring_reference>0</spring_reference>
          <spring_stiffness>0</spring_stiffness>
        </dynamics>
      </axis>
    </joint>
    <link name='head_2_link'>
      <pose relative_to='head_2_joint'>0 0 0 0 0 0</pose>
      <inertial>
        <pose>0.0558273798383187 0.06099870970651574 1.585423877870835e-05 0 0 0</pose>
        <mass>0.88693</mass>
        <inertia>
          <ixx>0.004770622192751422</ixx>
          <ixy>0.00056091591358651367</ixy>
          <ixz>1.194153304433451e-05</ixz>
          <iyy>0.0051336792437540416</iyy>
          <iyz>9.326472234409146e-06</iyz>
          <izz>0.0034759798898533921</izz>
        </inertia>
      </inertial>
      <collision name='head_2_link_collision'>
        <pose>0 0 0 0 0 0</pose>
        <geometry>
          <mesh>
            <scale>1 1 1</scale>
            <uri>meshes/head/head_2_collision.dae</uri>
          </mesh>
        </geometry>
      </collision>
      <visual name='head_2_link_visual'>
        <pose>0 0 0 0 0 0</pose>
        <geometry>
          <mesh>
            <scale>1 1 1</scale>
            <uri>meshes/head/head_2.stl</uri>
          </mesh>
        </geometry>
        <material>
          <diffuse>1 1 1 1</diffuse>
          <ambient>1 1 1 1</ambient>
        </material>
      </visual>
      <sensor name='head_front_camera_frame_sensor' type='depth'>
        <always_on>true</always_on>
        <update_rate>30</update_rate>
        <camera>
          <horizontal_fov>1.0995574287564276</horizontal_fov>
          <image>
            <format>B8G8R8</format>
            <width>640</width>
            <height>480</height>
          </image>
          <clip>
            <near>0.29999999999999999</near>
            <far>8</far>
          </clip>
          <distortion>
            <k1>1e-08</k1>
            <k2>1e-08</k2>
            <k3>1e-08</k3>
            <p1>1e-08</p1>
            <p2>1e-08</p2>
          </distortion>
        </camera>
        <pose>0.0908 0.08 -0.022 -1.5708 0 0</pose>
      </sensor>
    </link>
    <frame name='base_antenna_left_joint' attached_to='base_link'>
      <pose>-0.201 0.1062 0.195 0 -0 0</pose>
    </frame>
    <frame name='base_antenna_left_link' attached_to='base_antenna_left_joint'/>
    <frame name='base_antenna_right_joint' attached_to='base_link'>
      <pose>-0.201 -0.1062 0.195 0 -0 0</pose>
    </frame>
    <frame name='base_antenna_right_link' attached_to='base_antenna_right_joint'/>
    <frame name='base_dock' attached_to='base_link'>
      <pose>0.2675 0 0.061 0 -0 0</pose>
    </frame>
    <frame name='base_dock_link' attached_to='base_dock'/>
    <frame name='base_imu_joint' attached_to='base_link'>
      <pose>0.10171 0 0.11282 0 0 -1.5708</pose>
    </frame>
    <frame name='base_imu_link' attached_to='base_imu_joint'/>
    <frame name='base_laser_joint' attached_to='base_link'>
      <pose>0.202 0 -0.004 0 -0 0</pose>
    </frame>
    <frame name='base_laser_link' attached_to='base_laser_joint'/>
    <frame name='base_mic_back_left_joint' attached_to='base_link'>
      <pose>-0.1082 -0.0599 0.195 0 -0 0</pose>
    </frame>
    <frame name='base_mic_back_left_link' attached_to='base_mic_back_left_joint'/>
    <frame name='base_mic_back_right_joint' attached_to='base_link'>
      <pose>-0.1082 -0.13789 0.195 0 -0 0</pose>
    </frame>
    <frame name='base_mic_back_right_link' attached_to='base_mic_back_right_joint'/>
    <frame name='base_mic_front_left_joint' attached_to='base_link'>
      <pose>0.23182 0.03902 0.195 0 -0 0</pose>
    </frame>
    <frame name='base_mic_front_left_link' attached_to='base_mic_front_left_joint'/>
    <frame name='base_mic_front_right_joint' attached_to='base_link'>
      <pose>0.23182 -0.03902 0.195 0 -0 0</pose>
    </frame>
    <frame name='base_mic_front_right_link' attached_to='base_mic_front_right_joint'/>
    <frame name='base_sonar_01_joint' attached_to='base_link'>
      <pose>-0.183 -0.183 0.173 0 -0 -2.35619</pose>
    </frame>
    <frame name='base_sonar_01_link' attached_to='base_sonar_01_joint'/>
    <frame name='base_sonar_02_joint' attached_to='base_link'>
      <pose>-0.259 0 0.173 0 -0 3.14159</pose>
    </frame>
    <frame name='base_sonar_02_link' attached_to='base_sonar_02_joint'/>
    <frame name='base_sonar_03_joint' attached_to='base_link'>
      <pose>-0.183 0.183 0.173 0 -0 2.35619</pose>
    </frame>
    <frame name='base_sonar_03_link' attached_to='base_sonar_03_joint'/>
    <frame name='caster_back_left_2_joint' attached_to='caster_back_left_1_link'>
      <pose>-0.016 0 -0.04 -1.5708 0 0</pose>
    </frame>
    <frame name='caster_back_left_2_link' attached_to='caster_back_left_2_joint'/>
    <frame name='caster_back_left_1_joint' attached_to='base_link'>
      <pose>-0.1735 0.102 -0.0335 0 -0 0</pose>
    </frame>
    <frame name='caster_back_left_1_link' attached_to='caster_back_left_1_joint'/>
    <frame name='caster_back_right_2_joint' attached_to='caster_back_right_1_link'>
      <pose>-0.016 0 -0.04 -1.5708 0 0</pose>
    </frame>
    <frame name='caster_back_right_2_link' attached_to='caster_back_right_2_joint'/>
    <frame name='caster_back_right_1_joint' attached_to='base_link'>
      <pose>-0.1735 -0.102 -0.0335 0 -0 0</pose>
    </frame>
    <frame name='caster_back_right_1_link' attached_to='caster_back_right_1_joint'/>
    <frame name='caster_front_left_2_joint' attached_to='caster_front_left_1_link'>
      <pose>-0.016 0 -0.04 -1.5708 0 0</pose>
    </frame>
    <frame name='caster_front_left_2_link' attached_to='caster_front_left_2_joint'/>
    <frame name='caster_front_left_1_joint' attached_to='base_link'>
      <pose>0.1695 0.102 -0.0335 0 -0 0</pose>
    </frame>
    <frame name='caster_front_left_1_link' attached_to='caster_front_left_1_joint'/>
    <frame name='caster_front_right_2_joint' attached_to='caster_front_right_1_link'>
      <pose>-0.016 0 -0.04 -1.5708 0 0</pose>
    </frame>
    <frame name='caster_front_right_2_link' attached_to='caster_front_right_2_joint'/>
    <frame name='caster_front_right_1_joint' attached_to='base_link'>
      <pose>0.1695 -0.102 -0.0335 0 -0 0</pose>
    </frame>
    <frame name='caster_front_right_1_link' attached_to='caster_front_right_1_joint'/>
    <frame name='suspension_left_joint' attached_to='base_link'>
      <pose>0 0 0 0 -0 0</pose>
    </frame>
    <frame name='suspension_left_link' attached_to='suspension_left_joint'/>
    <frame name='suspension_right_joint' attached_to='base_link'>
      <pose>0 0 0 0 -0 0</pose>
    </frame>
    <frame name='suspension_right_link' attached_to='suspension_right_joint'/>
    <frame name='torso_fixed_column_joint' attached_to='base_link'>
      <pose>-0.062 0 0.193 0 -0 0</pose>
    </frame>
    <frame name='torso_fixed_column_link' attached_to='torso_fixed_column_joint'/>
    <frame name='torso_fixed_joint' attached_to='base_link'>
      <pose>-0.062 0 0.193 0 -0 0</pose>
    </frame>
    <frame name='torso_fixed_link' attached_to='torso_fixed_joint'/>
    <frame name='arm_tool_joint' attached_to='arm_7_link'>
      <pose>0 0 0.051875 -1.5708 -1.5708 0</pose>
    </frame>
    <frame name='arm_tool_link' attached_to='arm_tool_joint'/>
    <frame name='hand_grasping_fixed_joint' attached_to='hand_palm_link'>
      <pose>0.13 0.02 0 0 -0 0</pose>
    </frame>
    <frame name='hand_grasping_frame' attached_to='hand_grasping_fixed_joint'/>
    <frame name='hand_palm_joint' attached_to='wrist_ft_tool_link'>
      <pose>0 0 0 0 -0 0</pose>
    </frame>
    <frame name='hand_palm_link' attached_to='hand_palm_joint'/>
    <frame name='hand_safety_box_joint' attached_to='wrist_ft_tool_link'>
      <pose>0.1 0.02 0.02 0 -0 0</pose>
    </frame>
    <frame name='hand_safety_box' attached_to='hand_safety_box_joint'/>
    <frame name='hand_tool_joint' attached_to='wrist_ft_tool_link'>
      <pose>0 0 0 0 -0 0</pose>
    </frame>
    <frame name='hand_tool_link' attached_to='hand_tool_joint'/>
    <frame name='wrist_tool_joint' attached_to='wrist_ft_link'>
      <pose>0 0 0.0112 0 -1.5708 0</pose>
    </frame>
    <frame name='wrist_ft_tool_link' attached_to='wrist_tool_joint'/>
    <frame name='head_front_camera_optical_joint' attached_to='head_front_camera_link'>
      <pose>0 0 0 -1.5708 -0 -1.5708</pose>
    </frame>
    <frame name='head_front_camera_optical_frame' attached_to='head_front_camera_optical_joint'/>
    <frame name='head_front_camera_color_optical_joint' attached_to='head_front_camera_color_frame'>
      <pose>0 0 0 -1.5708 -0 -1.5708</pose>
    </frame>
    <frame name='head_front_camera_color_optical_frame' attached_to='head_front_camera_color_optical_joint'/>
    <frame name='head_front_camera_depth_optical_joint' attached_to='head_front_camera_depth_frame'>
      <pose>0 0 0 -1.5708 -0 -1.5708</pose>
    </frame>
    <frame name='head_front_camera_depth_optical_frame' attached_to='head_front_camera_depth_optical_joint'/>
    <frame name='head_front_camera_depth_joint' attached_to='head_front_camera_color_frame'>
      <pose>0 0.025 0 0 -0 0</pose>
    </frame>
    <frame name='head_front_camera_depth_frame' attached_to='head_front_camera_depth_joint'/>
    <frame name='head_front_camera_color_joint' attached_to='head_front_camera_orbbec_aux_joint_frame'>
      <pose>0 0.022 0 0 -0 0</pose>
    </frame>
    <frame name='head_front_camera_color_frame' attached_to='head_front_camera_color_joint'/>
    <frame name='head_front_camera_orbbec_aux_joint' attached_to='head_front_camera_link'>
      <pose>0 0 0 0 -0 0</pose>
    </frame>
    <frame name='head_front_camera_orbbec_aux_joint_frame' attached_to='head_front_camera_orbbec_aux_joint'/>
    <frame name='head_front_camera_joint' attached_to='head_2_link'>
      <pose>0.0908 0.08 0 -1.5708 0 0</pose>
    </frame>
    <frame name='head_front_camera_link' attached_to='head_front_camera_joint'/>
    <frame name='base_footprint_joint' attached_to='base_footprint'>
      <pose>0 0 0.0985 0 -0 0</pose>
    </frame>
    <frame name='base_link' attached_to='base_footprint_joint'/>
    <frame name='cover_joint' attached_to='base_footprint'>
      <pose>0 0 0.13 0 -0 0</pose>
    </frame>
    <frame name='base_cover_link' attached_to='cover_joint'/>
  </model>
</sdf>
