<sdf version='1.7'>
  <model name='tiago'>
    <link name='base_footprint'>
      <inertial>
        <pose>-0.006615 -0.001027 0.169499 0 -0 0</pose>
        <mass>63.4328</mass>
        <inertia>
          <ixx>4.28569</ixx>
          <ixy>0.000534576</ixy>
          <ixz>0.127532</ixz>
          <iyy>4.37782</iyy>
          <iyz>0.0168155</iyz>
          <izz>2.69271</izz>
        </inertia>
      </inertial>
      <collision name='base_footprint_fixed_joint_lump__base_link_collision'>
        <pose>0 0 0.0985 0 -0 0</pose>
        <geometry>
          <mesh>
            <scale>1 1 1</scale>
            <uri>../../../../pmb2_robot/pmb2_description/meshes/base/high_resolution/base_collision.stl</uri>
          </mesh>
        </geometry>
        <surface>
          <contact>
            <ode/>
          </contact>
          <friction>
            <ode/>
          </friction>
        </surface>
      </collision>
      <collision name='base_footprint_fixed_joint_lump__base_antenna_left_link_collision_1'>
        <pose>-0.201 0.1062 0.3785 0 -0 0</pose>
        <geometry>
          <cylinder>
            <length>0.17</length>
            <radius>0.005</radius>
          </cylinder>
        </geometry>
        <surface>
          <contact>
            <ode/>
          </contact>
          <friction>
            <ode/>
          </friction>
        </surface>
      </collision>
      <collision name='base_footprint_fixed_joint_lump__base_antenna_right_link_collision_2'>
        <pose>-0.201 -0.1062 0.3785 0 -0 0</pose>
        <geometry>
          <cylinder>
            <length>0.17</length>
            <radius>0.005</radius>
          </cylinder>
        </geometry>
        <surface>
          <contact>
            <ode/>
          </contact>
          <friction>
            <ode/>
          </friction>
        </surface>
      </collision>
      <collision name='base_footprint_fixed_joint_lump__base_dock_link_collision_3'>
        <pose>0.2675 0 0.1595 0 -0 0</pose>
        <geometry>
          <mesh>
            <scale>1 1 1</scale>
            <uri>../../../../pmb2_robot/pmb2_description/meshes/base/base_dock_link.stl</uri>
          </mesh>
        </geometry>
      </collision>
      <collision name='base_footprint_fixed_joint_lump__base_laser_link_collision_4'>
        <pose>0.202 0 0.0945 0 -0 0</pose>
        <geometry>
          <cylinder>
            <length>0.01</length>
            <radius>0.01</radius>
          </cylinder>
        </geometry>
        <surface>
          <contact>
            <ode/>
          </contact>
          <friction>
            <ode/>
          </friction>
        </surface>
      </collision>
      <collision name='base_footprint_fixed_joint_lump__caster_back_left_2_link_collision_5'>
        <pose>-0.1895 0.102 0.025 -1.5708 0 0</pose>
        <geometry>
          <sphere>
            <radius>0.025</radius>
          </sphere>
        </geometry>
        <surface>
          <contact>
            <ode>
              <kp>1e+06</kp>
              <kd>100</kd>
              <max_vel>1</max_vel>
              <min_depth>0.002</min_depth>
            </ode>
          </contact>
          <friction>
            <ode>
              <mu>0.01</mu>
              <mu2>0.01</mu2>
            </ode>
          </friction>
        </surface>
      </collision>
      <collision name='base_footprint_fixed_joint_lump__caster_back_right_2_link_collision_6'>
        <pose>-0.1895 -0.102 0.025 -1.5708 0 0</pose>
        <geometry>
          <sphere>
            <radius>0.025</radius>
          </sphere>
        </geometry>
        <surface>
          <contact>
            <ode>
              <kp>1e+06</kp>
              <kd>100</kd>
              <max_vel>1</max_vel>
              <min_depth>0.002</min_depth>
            </ode>
          </contact>
          <friction>
            <ode>
              <mu>0.01</mu>
              <mu2>0.01</mu2>
            </ode>
          </friction>
        </surface>
      </collision>
      <collision name='base_footprint_fixed_joint_lump__caster_front_left_2_link_collision_7'>
        <pose>0.1535 0.102 0.025 -1.5708 0 0</pose>
        <geometry>
          <sphere>
            <radius>0.025</radius>
          </sphere>
        </geometry>
        <surface>
          <contact>
            <ode>
              <kp>1e+06</kp>
              <kd>100</kd>
              <max_vel>1</max_vel>
              <min_depth>0.002</min_depth>
            </ode>
          </contact>
          <friction>
            <ode>
              <mu>0.01</mu>
              <mu2>0.01</mu2>
            </ode>
          </friction>
        </surface>
      </collision>
      <collision name='base_footprint_fixed_joint_lump__caster_front_right_2_link_collision_8'>
        <pose>0.1535 -0.102 0.025 -1.5708 0 0</pose>
        <geometry>
          <sphere>
            <radius>0.025</radius>
          </sphere>
        </geometry>
        <surface>
          <contact>
            <ode>
              <kp>1e+06</kp>
              <kd>100</kd>
              <max_vel>1</max_vel>
              <min_depth>0.002</min_depth>
            </ode>
          </contact>
          <friction>
            <ode>
              <mu>0.01</mu>
              <mu2>0.01</mu2>
            </ode>
          </friction>
        </surface>
      </collision>
      <collision name='base_footprint_fixed_joint_lump__torso_fixed_column_link_collision_9'>
        <pose>-0.062 0 0.5665 0 -0 0</pose>
        <geometry>
          <box>
            <size>0.232 0.265 0.45</size>
          </box>
        </geometry>
        <surface>
          <contact>
            <ode/>
          </contact>
          <friction>
            <ode/>
          </friction>
        </surface>
      </collision>
      <collision name='base_footprint_fixed_joint_lump__torso_fixed_link_collision_10'>
        <pose>0.023 0 0.3115 0 -0 0</pose>
        <geometry>
          <box>
            <size>0.4 0.25 0.04</size>
          </box>
        </geometry>
      </collision>
      <collision name='base_footprint_fixed_joint_lump__torso_fixed_link_collision_11'>
        <pose>-0.062 0 0.3415 0 -0 0</pose>
        <geometry>
          <box>
            <size>0.25 0.25 0.1</size>
          </box>
        </geometry>
      </collision>
      <visual name='base_footprint_fixed_joint_lump__base_link_visual'>
        <pose>0 0 0.0985 0 -0 0</pose>
        <geometry>
          <mesh>
            <scale>1 1 1</scale>
            <uri>../../../../pmb2_robot/pmb2_description/meshes/base/base.stl</uri>
          </mesh>
        </geometry>
        <material>
          <script>
            <name>Gazebo/White</name>
            <uri>file://media/materials/scripts/gazebo.material</uri>
          </script>
        </material>
      </visual>
      <visual name='base_footprint_fixed_joint_lump__base_antenna_left_link_visual_1'>
        <pose>-0.201 0.1062 0.2935 0 -0 0</pose>
        <geometry>
          <mesh>
            <scale>1 1 1</scale>
            <uri>../../../../pmb2_robot/pmb2_description/meshes/objects/antenna.stl</uri>
          </mesh>
        </geometry>
        <material>
          <script>
            <name>Gazebo/Black</name>
            <uri>file://media/materials/scripts/gazebo.material</uri>
          </script>
        </material>
      </visual>
      <visual name='base_footprint_fixed_joint_lump__base_antenna_right_link_visual_2'>
        <pose>-0.201 -0.1062 0.2935 0 -0 0</pose>
        <geometry>
          <mesh>
            <scale>1 1 1</scale>
            <uri>../../../../pmb2_robot/pmb2_description/meshes/objects/antenna.stl</uri>
          </mesh>
        </geometry>
        <material>
          <script>
            <name>Gazebo/Black</name>
            <uri>file://media/materials/scripts/gazebo.material</uri>
          </script>
        </material>
      </visual>
      <visual name='base_footprint_fixed_joint_lump__base_dock_link_visual_3'>
        <pose>0.2675 0 0.1595 0 -0 0</pose>
        <geometry>
          <mesh>
            <scale>1 1 1</scale>
            <uri>../../../../pmb2_robot/pmb2_description/meshes/base/base_dock_link.stl</uri>
          </mesh>
        </geometry>
      </visual>
      <visual name='base_footprint_fixed_joint_lump__base_laser_link_visual_4'>
        <pose>0.202 0 0.0945 0 -0 0</pose>
        <geometry>
          <mesh>
            <scale>1 1 1</scale>
            <uri>../../../../pal_urdf_utils/meshes/laser/sick_tim551.stl</uri>
          </mesh>
        </geometry>
        <material>
          <script>
            <name>Gazebo/DarkGrey</name>
            <uri>file://media/materials/scripts/gazebo.material</uri>
          </script>
        </material>
      </visual>
      <visual name='base_footprint_fixed_joint_lump__base_sonar_01_link_visual_5'>
        <pose>-0.183 -0.183 0.2715 0 0 -2.35619</pose>
        <geometry>
          <mesh>
            <scale>1 1 1</scale>
            <uri>../../../../pal_urdf_utils/meshes/laser/srf05.stl</uri>
          </mesh>
        </geometry>
        <material>
          <script>
            <name>Gazebo/DarkGrey</name>
            <uri>file://media/materials/scripts/gazebo.material</uri>
          </script>
        </material>
      </visual>
      <visual name='base_footprint_fixed_joint_lump__base_sonar_02_link_visual_6'>
        <pose>-0.259 0 0.2715 0 -0 3.14159</pose>
        <geometry>
          <mesh>
            <scale>1 1 1</scale>
            <uri>../../../../pal_urdf_utils/meshes/laser/srf05.stl</uri>
          </mesh>
        </geometry>
        <material>
          <script>
            <name>Gazebo/DarkGrey</name>
            <uri>file://media/materials/scripts/gazebo.material</uri>
          </script>
        </material>
      </visual>
      <visual name='base_footprint_fixed_joint_lump__base_sonar_03_link_visual_7'>
        <pose>-0.183 0.183 0.2715 0 -0 2.35619</pose>
        <geometry>
          <mesh>
            <scale>1 1 1</scale>
            <uri>../../../../pal_urdf_utils/meshes/laser/srf05.stl</uri>
          </mesh>
        </geometry>
        <material>
          <script>
            <name>Gazebo/DarkGrey</name>
            <uri>file://media/materials/scripts/gazebo.material</uri>
          </script>
        </material>
      </visual>
      <visual name='base_footprint_fixed_joint_lump__caster_back_left_1_link_visual_8'>
        <pose>-0.1735 0.102 0.065 0 -0 0</pose>
        <geometry>
          <mesh>
            <scale>1 1 1</scale>
            <uri>../../../../pmb2_robot/pmb2_description/meshes/wheels/caster_1.stl</uri>
          </mesh>
        </geometry>
      </visual>
      <visual name='base_footprint_fixed_joint_lump__caster_back_left_2_link_visual_9'>
        <pose>-0.1895 0.102 0.025 -1.5708 0 0</pose>
        <geometry>
          <mesh>
            <scale>1 1 1</scale>
            <uri>../../../../pmb2_robot/pmb2_description/meshes/wheels/caster_2.stl</uri>
          </mesh>
        </geometry>
        <material>
          <script>
            <name>Gazebo/DarkGrey</name>
            <uri>file://media/materials/scripts/gazebo.material</uri>
          </script>
        </material>
      </visual>
      <visual name='base_footprint_fixed_joint_lump__caster_back_right_1_link_visual_10'>
        <pose>-0.1735 -0.102 0.065 0 -0 0</pose>
        <geometry>
          <mesh>
            <scale>1 1 1</scale>
            <uri>../../../../pmb2_robot/pmb2_description/meshes/wheels/caster_1.stl</uri>
          </mesh>
        </geometry>
      </visual>
      <visual name='base_footprint_fixed_joint_lump__caster_back_right_2_link_visual_11'>
        <pose>-0.1895 -0.102 0.025 -1.5708 0 0</pose>
        <geometry>
          <mesh>
            <scale>1 1 1</scale>
            <uri>../../../../pmb2_robot/pmb2_description/meshes/wheels/caster_2.stl</uri>
          </mesh>
        </geometry>
        <material>
          <script>
            <name>Gazebo/DarkGrey</name>
            <uri>file://media/materials/scripts/gazebo.material</uri>
          </script>
        </material>
      </visual>
      <visual name='base_footprint_fixed_joint_lump__caster_front_left_1_link_visual_12'>
        <pose>0.1695 0.102 0.065 0 -0 0</pose>
        <geometry>
          <mesh>
            <scale>1 1 1</scale>
            <uri>../../../../pmb2_robot/pmb2_description/meshes/wheels/caster_1.stl</uri>
          </mesh>
        </geometry>
      </visual>
      <visual name='base_footprint_fixed_joint_lump__caster_front_left_2_link_visual_13'>
        <pose>0.1535 0.102 0.025 -1.5708 0 0</pose>
        <geometry>
          <mesh>
            <scale>1 1 1</scale>
            <uri>../../../../pmb2_robot/pmb2_description/meshes/wheels/caster_2.stl</uri>
          </mesh>
        </geometry>
        <material>
          <script>
            <name>Gazebo/DarkGrey</name>
            <uri>file://media/materials/scripts/gazebo.material</uri>
          </script>
        </material>
      </visual>
      <visual name='base_footprint_fixed_joint_lump__caster_front_right_1_link_visual_14'>
        <pose>0.1695 -0.102 0.065 0 -0 0</pose>
        <geometry>
          <mesh>
            <scale>1 1 1</scale>
            <uri>../../../../pmb2_robot/pmb2_description/meshes/wheels/caster_1.stl</uri>
          </mesh>
        </geometry>
      </visual>
      <visual name='base_footprint_fixed_joint_lump__caster_front_right_2_link_visual_15'>
        <pose>0.1535 -0.102 0.025 -1.5708 0 0</pose>
        <geometry>
          <mesh>
            <scale>1 1 1</scale>
            <uri>../../../../pmb2_robot/pmb2_description/meshes/wheels/caster_2.stl</uri>
          </mesh>
        </geometry>
        <material>
          <script>
            <name>Gazebo/DarkGrey</name>
            <uri>file://media/materials/scripts/gazebo.material</uri>
          </script>
        </material>
      </visual>
      <visual name='base_footprint_fixed_joint_lump__torso_fixed_column_link_visual_16'>
        <pose>-0.062 0 0.5665 0 -0 0</pose>
        <geometry>
          <box>
            <size>0.18 0.2 0.55</size>
          </box>
        </geometry>
        <material>
          <script>
            <name>Gazebo/DarkGrey</name>
            <uri>file://media/materials/scripts/gazebo.material</uri>
          </script>
        </material>
      </visual>
      <visual name='base_footprint_fixed_joint_lump__torso_fixed_link_visual_17'>
        <pose>-0.062 0 0.2915 0 -0 0</pose>
        <geometry>
          <mesh>
            <scale>1 1 1</scale>
            <uri>../../meshes/torso/torso_fix.stl</uri>
          </mesh>
        </geometry>
      </visual>
      <visual name='base_footprint_fixed_joint_lump__base_cover_link_visual_18'>
        <pose>0 0 0.13 0 -0 0</pose>
        <geometry>
          <mesh>
            <scale>1 1 1</scale>
            <uri>../../../../pmb2_robot/pmb2_description/meshes/base/base_ring.stl</uri>
          </mesh>
        </geometry>
        <material>
          <script>
            <name>Gazebo/Orange</name>
            <uri>file://media/materials/scripts/gazebo.material</uri>
          </script>
        </material>
      </visual>
      <sensor name='base_imu_sensor' type='imu'>
        <always_on>1</always_on>
        <update_rate>100</update_rate>
        <imu>
          <noise>
            <type>gaussian</type>
            <rate>
              <mean>0.0</mean>
              <stddev>2e-4</stddev>
              <bias_mean>0.0000075</bias_mean>
              <bias_stddev>0.0000008</bias_stddev>
            </rate>
            <accel>
              <mean>0.0</mean>
              <stddev>1.7e-2</stddev>
              <bias_mean>0.1</bias_mean>
              <bias_stddev>0.001</bias_stddev>
            </accel>
          </noise>
        </imu>
        <plugin name='base_imu' filename='libgazebo_ros_imu_sensor.so'>
          <ros>
            <namespace/>
            <remapping>~/out:=base_imu</remapping>
          </ros>
        </plugin>
        <pose>0.10171 0 0.21132 0 0 -1.5708</pose>
      </sensor>
      <sensor name='base_laser' type='gpu_lidar'>
        <update_rate>10</update_rate>
        <visualize>true</visualize>
        <always_on>true</always_on>
        <topic>/scan</topic>
        <lidar>
          <scan>
            <horizontal>
              <samples>666</samples>
              <resolution>1</resolution>
              <min_angle>-1.9198621771937625</min_angle>
              <max_angle>1.9198621771937625</max_angle>
            </horizontal>
          </scan>
          <range>
            <min>0.05</min>
            <max>25</max>
            <resolution>0.001</resolution>
          </range>
          <noise>
            <type>gaussian</type>
            <mean>0</mean>
            <stddev>0.01</stddev>
          </noise>
        </lidar>
        <pose>0.202 0 0.0945 0 -0 0</pose>
      </sensor>
      <sensor name='base_sonar_01' type='gpu_ray'>
        <update_rate>5</update_rate>
        <visualize>0</visualize>
        <ray>
          <scan>
            <horizontal>
              <samples>5</samples>
              <resolution>1</resolution>
              <min_angle>-0.25</min_angle>
              <max_angle>0.25</max_angle>
            </horizontal>
            <vertical>
              <samples>5</samples>
              <resolution>1</resolution>
              <min_angle>-0.25</min_angle>
              <max_angle>0.25</max_angle>
            </vertical>
          </scan>
          <range>
            <min>0.02</min>
            <max>1</max>
            <resolution>0.01</resolution>
          </range>
          <noise>
            <type>gaussian</type>
            <mean>0</mean>
            <stddev>0.005</stddev>
          </noise>
        </ray>
        <plugin name='base_sonar_01_gazebo_ros_range' filename='libgazebo_ros_ray_sensor.so'>
          <ros>
            <namespace/>
            <remapping>~/out:=sonar_base</remapping>
          </ros>
          <output_type>sensor_msgs/Range</output_type>
          <radiation_type>ultrasound</radiation_type>
          <frame_name>base_sonar_01_link</frame_name>
        </plugin>
        <pose>-0.183 -0.183 0.2715 0 -0 -2.35619</pose>
      </sensor>
      <sensor name='base_sonar_02' type='gpu_ray'>
        <update_rate>5</update_rate>
        <visualize>0</visualize>
        <ray>
          <scan>
            <horizontal>
              <samples>5</samples>
              <resolution>1</resolution>
              <min_angle>-0.25</min_angle>
              <max_angle>0.25</max_angle>
            </horizontal>
            <vertical>
              <samples>5</samples>
              <resolution>1</resolution>
              <min_angle>-0.25</min_angle>
              <max_angle>0.25</max_angle>
            </vertical>
          </scan>
          <range>
            <min>0.02</min>
            <max>1</max>
            <resolution>0.01</resolution>
          </range>
          <noise>
            <type>gaussian</type>
            <mean>0</mean>
            <stddev>0.005</stddev>
          </noise>
        </ray>
        <plugin name='base_sonar_02_gazebo_ros_range' filename='libgazebo_ros_ray_sensor.so'>
          <ros>
            <namespace/>
            <remapping>~/out:=sonar_base</remapping>
          </ros>
          <output_type>sensor_msgs/Range</output_type>
          <radiation_type>ultrasound</radiation_type>
          <frame_name>base_sonar_02_link</frame_name>
        </plugin>
        <pose>-0.259 0 0.2715 0 -0 3.14159</pose>
      </sensor>
      <sensor name='base_sonar_03' type='gpu_ray'>
        <update_rate>5</update_rate>
        <visualize>0</visualize>
        <ray>
          <scan>
            <horizontal>
              <samples>5</samples>
              <resolution>1</resolution>
              <min_angle>-0.25</min_angle>
              <max_angle>0.25</max_angle>
            </horizontal>
            <vertical>
              <samples>5</samples>
              <resolution>1</resolution>
              <min_angle>-0.25</min_angle>
              <max_angle>0.25</max_angle>
            </vertical>
          </scan>
          <range>
            <min>0.02</min>
            <max>1</max>
            <resolution>0.01</resolution>
          </range>
          <noise>
            <type>gaussian</type>
            <mean>0</mean>
            <stddev>0.005</stddev>
          </noise>
        </ray>
        <plugin name='base_sonar_03_gazebo_ros_range' filename='libgazebo_ros_ray_sensor.so'>
          <ros>
            <namespace/>
            <remapping>~/out:=sonar_base</remapping>
          </ros>
          <output_type>sensor_msgs/Range</output_type>
          <radiation_type>ultrasound</radiation_type>
          <frame_name>base_sonar_03_link</frame_name>
        </plugin>
        <pose>-0.183 0.183 0.2715 0 -0 2.35619</pose>
      </sensor>
    </link>
    <joint name='wheel_left_joint' type='revolute'>
      <pose relative_to='base_footprint'>0 0.2022 0.0985 -1.5708 0 0</pose>
      <parent>base_footprint</parent>
      <child>wheel_left_link</child>
      <axis>
        <xyz>0 0 1</xyz>
        <limit>
          <effort>6</effort>
          <velocity>100</velocity>
          <lower>-1e+16</lower>
          <upper>1e+16</upper>
        </limit>
        <dynamics>
          <damping>1</damping>
          <friction>2</friction>
          <spring_reference>0</spring_reference>
          <spring_stiffness>0</spring_stiffness>
        </dynamics>
      </axis>
    </joint>
    <link name='wheel_left_link'>
      <pose relative_to='wheel_left_joint'>0 0 0 0 -0 0</pose>
      <inertial>
        <pose>0 0 0.00207 0 -0 0</pose>
        <mass>1.82362</mass>
        <inertia>
          <ixx>0.00499743</ixx>
          <ixy>-4.464e-08</ixy>
          <ixz>-2.245e-08</ixz>
          <iyy>0.00499742</iyy>
          <iyz>1.64e-09</iyz>
          <izz>0.0083924</izz>
        </inertia>
      </inertial>
      <collision name='wheel_left_link_collision'>
        <pose>0 0 0 0 -0 0</pose>
        <geometry>
          <cylinder>
            <length>0.04</length>
            <radius>0.0985</radius>
          </cylinder>
        </geometry>
        <surface>
          <contact>
            <ode>
              <kp>1e+06</kp>
              <kd>100</kd>
              <max_vel>1</max_vel>
              <min_depth>0.002</min_depth>
            </ode>
          </contact>
          <friction>
            <ode>
              <mu>1</mu>
              <mu2>1</mu2>
            </ode>
          </friction>
        </surface>
      </collision>
      <visual name='wheel_left_link_visual'>
        <pose>0 0 0 -3.14159 0 0</pose>
        <geometry>
          <mesh>
            <scale>1 1 1</scale>
            <uri>../../../../pmb2_robot/pmb2_description/meshes/wheels/wheel.stl</uri>
          </mesh>
        </geometry>
        <material>
          <script>
            <name>Gazebo/DarkGrey</name>
            <uri>file://media/materials/scripts/gazebo.material</uri>
          </script>
        </material>
      </visual>
    </link>
    <joint name='wheel_right_joint' type='revolute'>
      <pose relative_to='base_footprint'>0 -0.2022 0.0985 -1.5708 0 0</pose>
      <parent>base_footprint</parent>
      <child>wheel_right_link</child>
      <axis>
        <xyz>0 0 1</xyz>
        <limit>
          <effort>6</effort>
          <velocity>100</velocity>
          <lower>-1e+16</lower>
          <upper>1e+16</upper>
        </limit>
        <dynamics>
          <damping>1</damping>
          <friction>2</friction>
          <spring_reference>0</spring_reference>
          <spring_stiffness>0</spring_stiffness>
        </dynamics>
      </axis>
    </joint>
    <link name='wheel_right_link'>
      <pose relative_to='wheel_right_joint'>0 0 0 0 -0 0</pose>
      <inertial>
        <pose>0 0 -0.00207 0 -0 0</pose>
        <mass>1.82362</mass>
        <inertia>
          <ixx>0.00499743</ixx>
          <ixy>4.464e-08</ixy>
          <ixz>-2.245e-08</ixz>
          <iyy>0.00499742</iyy>
          <iyz>-1.64e-09</iyz>
          <izz>0.0083924</izz>
        </inertia>
      </inertial>
      <collision name='wheel_right_link_collision'>
        <pose>0 0 0 0 -0 0</pose>
        <geometry>
          <cylinder>
            <length>0.04</length>
            <radius>0.0985</radius>
          </cylinder>
        </geometry>
        <surface>
          <contact>
            <ode>
              <kp>1e+06</kp>
              <kd>100</kd>
              <max_vel>1</max_vel>
              <min_depth>0.002</min_depth>
            </ode>
          </contact>
          <friction>
            <ode>
              <mu>1</mu>
              <mu2>1</mu2>
            </ode>
          </friction>
        </surface>
      </collision>
      <visual name='wheel_right_link_visual'>
        <pose>0 0 0 0 -0 0</pose>
        <geometry>
          <mesh>
            <scale>1 1 1</scale>
            <uri>../../../../pmb2_robot/pmb2_description/meshes/wheels/wheel.stl</uri>
          </mesh>
        </geometry>
        <material>
          <script>
            <name>Gazebo/DarkGrey</name>
            <uri>file://media/materials/scripts/gazebo.material</uri>
          </script>
        </material>
      </visual>
    </link>
    <joint name='torso_lift_joint' type='prismatic'>
      <pose relative_to='base_footprint'>-0.062 0 0.8885 0 -0 0</pose>
      <parent>base_footprint</parent>
      <child>torso_lift_link</child>
      <axis>
        <xyz>0 0 1</xyz>
        <limit>
          <lower>0</lower>
          <upper>0.35</upper>
          <effort>2000</effort>
          <velocity>0.07</velocity>
        </limit>
        <dynamics>
          <damping>1000</damping>
          <friction>0</friction>
          <spring_reference>0</spring_reference>
          <spring_stiffness>0</spring_stiffness>
        </dynamics>
      </axis>
    </joint>
    <link name='torso_lift_link'>
      <pose relative_to='torso_lift_joint'>0 0 0 0 -0 0</pose>
      <inertial>
        <pose>0.04361 -0.00116 -0.17334 0 -0 0</pose>
        <mass>6.93198</mass>
        <inertia>
          <ixx>0.24487</ixx>
          <ixy>-0.001456</ixy>
          <ixz>-0.009742</ixz>
          <iyy>0.249269</iyy>
          <iyz>0.008281</iyz>
          <izz>0.090395</izz>
        </inertia>
      </inertial>
      <collision name='torso_lift_link_collision'>
        <pose>0 0 0 0 -0 0</pose>
        <geometry>
          <mesh>
            <scale>1 1 1</scale>
            <uri>../../meshes/torso/torso_lift_collision_core.dae</uri>
          </mesh>
        </geometry>
      </collision>
      <collision name='torso_lift_link_collision_1'>
        <pose>0 0 0 0 -0 0</pose>
        <geometry>
          <mesh>
            <scale>1 1 1</scale>
            <uri>../../meshes/torso/torso_lift_collision_shoulder.dae</uri>
          </mesh>
        </geometry>
      </collision>
      <collision name='torso_lift_link_collision_2'>
        <pose>0 0 0 0 -0 0</pose>
        <geometry>
          <mesh>
            <scale>1 1 1</scale>
            <uri>../../meshes/torso/torso_lift_collision_neck.dae</uri>
          </mesh>
        </geometry>
      </collision>
      <visual name='torso_lift_link_visual'>
        <pose>0 0 0 0 -0 0</pose>
        <geometry>
          <mesh>
            <scale>1 1 1</scale>
            <uri>../../meshes/torso/torso_lift_with_arm.stl</uri>
          </mesh>
        </geometry>
      </visual>
    </link>
    <joint name='head_1_joint' type='revolute'>
      <pose relative_to='torso_lift_link'>0.182 0 0 0 -0 0</pose>
      <parent>torso_lift_link</parent>
      <child>head_1_link</child>
      <axis>
        <xyz>0 0 1</xyz>
        <limit>
          <lower>-1.309</lower>
          <upper>1.309</upper>
          <effort>5.197</effort>
          <velocity>3</velocity>
        </limit>
        <dynamics>
          <damping>0.5</damping>
          <friction>1</friction>
          <spring_reference>0</spring_reference>
          <spring_stiffness>0</spring_stiffness>
        </dynamics>
      </axis>
      <physics>
        <ode>
          <implicit_spring_damper>1</implicit_spring_damper>
          <cfm_damping>1</cfm_damping>
          <limit>
            <cfm>0</cfm>
            <erp>0.2</erp>
          </limit>
        </ode>
      </physics>
    </joint>
    <link name='head_1_link'>
      <pose relative_to='head_1_joint'>0 0 0 0 -0 0</pose>
      <inertial>
        <pose>-0.00508 0.00237 0.07229 0 -0 0</pose>
        <mass>0.6222</mass>
        <inertia>
          <ixx>0.001192</ixx>
          <ixy>-7e-06</ixy>
          <ixz>9.6e-05</ixz>
          <iyy>0.001402</iyy>
          <iyz>4e-06</iyz>
          <izz>0.000889</izz>
        </inertia>
      </inertial>
      <collision name='head_1_link_collision'>
        <pose>0 0 0 0 -0 0</pose>
        <geometry>
          <mesh>
            <scale>1 1 1</scale>
            <uri>../../meshes/head/head_1_collision.dae</uri>
          </mesh>
        </geometry>
        <surface>
          <contact>
            <ode/>
          </contact>
          <friction>
            <ode>
              <mu>0.9</mu>
              <mu2>0.9</mu2>
            </ode>
          </friction>
        </surface>
      </collision>
      <visual name='head_1_link_visual'>
        <pose>0 0 0 0 -0 0</pose>
        <geometry>
          <mesh>
            <scale>1 1 1</scale>
            <uri>../../meshes/head/head_1.stl</uri>
          </mesh>
        </geometry>
      </visual>
    </link>
    <joint name='head_2_joint' type='revolute'>
      <pose relative_to='head_1_link'>0.005 0 0.098 1.5708 -0 0</pose>
      <parent>head_1_link</parent>
      <child>head_2_link</child>
      <axis>
        <xyz>0 0 1</xyz>
        <limit>
          <lower>-1.0472</lower>
          <upper>0.785398</upper>
          <effort>2.77</effort>
          <velocity>3</velocity>
        </limit>
        <dynamics>
          <damping>0.5</damping>
          <friction>1</friction>
          <spring_reference>0</spring_reference>
          <spring_stiffness>0</spring_stiffness>
        </dynamics>
      </axis>
    </joint>
    <link name='head_2_link'>
      <pose relative_to='head_2_joint'>0 0 0 0 -0 0</pose>
      <inertial>
        <pose>0.055827 0.060999 1.6e-05 0 -0 0</pose>
        <mass>0.88693</mass>
        <inertia>
          <ixx>0.00477062</ixx>
          <ixy>0.000560916</ixy>
          <ixz>1.19415e-05</ixz>
          <iyy>0.00513368</iyy>
          <iyz>9.32647e-06</iyz>
          <izz>0.00347598</izz>
        </inertia>
      </inertial>
      <collision name='head_2_link_collision'>
        <pose>0 0 0 0 -0 0</pose>
        <geometry>
          <mesh>
            <scale>1 1 1</scale>
            <uri>../../meshes/head/head_2_collision.dae</uri>
          </mesh>
        </geometry>
      </collision>
      <visual name='head_2_link_visual'>
        <pose>0 0 0 0 -0 0</pose>
        <geometry>
          <mesh>
            <scale>1 1 1</scale>
            <uri>../../meshes/head/head_2.stl</uri>
          </mesh>
        </geometry>
      </visual>
      <sensor name='head_front_camera_frame_sensor' type='depth'>
        <always_on>1</always_on>
        <update_rate>30</update_rate>
        <camera>
          <horizontal_fov>1.09956</horizontal_fov>
          <image>
            <format>B8G8R8</format>
            <width>640</width>
            <height>480</height>
          </image>
          <clip>
            <near>0.3</near>
            <far>8</far>
          </clip>
          <distortion>
            <k1>1e-08</k1>
            <k2>1e-08</k2>
            <k3>1e-08</k3>
            <p1>1e-08</p1>
            <p2>1e-08</p2>
          </distortion>
        </camera>
        <plugin name='head_front_camera_frame_controller' filename='libgazebo_ros_camera.so'>
          <camera_name>head_front_camera</camera_name>
          <ros>
            <remapping>head_front_camera/image_raw:=head_front_camera/rgb/image_raw</remapping>
            <remapping>head_front_camera/camera_info:=head_front_camera/rgb/camera_info</remapping>
            <remapping>head_front_camera/depth/image_raw:=head_front_camera/depth/image_raw</remapping>
            <remapping>head_front_camera/depth/camera_info:=head_front_camera/depth/camera_info</remapping>
            <remapping>head_front_camera/points:=head_front_camera/depth/points</remapping>
          </ros>
          <frame_name>head_front_camera_color_optical_frame</frame_name>
          <min_depth>0.3</min_depth>
          <max_depth>8.0</max_depth>
        </plugin>
        <pose>0.0908 0.08 -0.022 -1.5708 0 0</pose>
      </sensor>
    </link>
    <static>0</static>
    <!-- Ignition DiffDrive 插件 - 发布 /odom 和控制移动 -->
    <plugin filename="ignition-gazebo-diff-drive-system" name="ignition::gazebo::systems::DiffDrive">
      <left_joint>wheel_left_joint</left_joint>
      <right_joint>wheel_right_joint</right_joint>
      <wheel_separation>0.4044</wheel_separation>
      <wheel_radius>0.0985</wheel_radius>
      <max_linear_acceleration>1.0</max_linear_acceleration>
      <min_linear_acceleration>-1.0</min_linear_acceleration>
      <max_angular_acceleration>2.0</max_angular_acceleration>
      <min_angular_acceleration>-2.0</min_angular_acceleration>
      <topic>/cmd_vel</topic>
      <odom_topic>/odom</odom_topic>
      <frame_id>odom</frame_id>
      <child_frame_id>base_footprint</child_frame_id>
      <publish_odom>true</publish_odom>
      <publish_odom_tf>true</publish_odom_tf>
      <tf_topic>/tf</tf_topic>
    </plugin>

    <!-- 关节状态发布插件 -->
    <plugin filename="ignition-gazebo-joint-state-publisher-system" name="ignition::gazebo::systems::JointStatePublisher">
      <topic>/joint_states</topic>
    </plugin>

  </model>
</sdf>
